Workbook

Sheet Resumo
A1: PEDIDO PALMED — 20/10/2026 — DROGARIAS ROCHA
A2: Prazo de pagamento solicitado: MÍNIMO 45 DIAS — preferência até 90 DIAS (ex.: 45/60/75/90 dd ou 90 dd direto)
A4: Setor logístico | B4: Itens | C4: Caixas | D4: Valor
A5: CASTANHAL | B5: =COUNT('Setor CASTANHAL'!A9:A72) -> 64 | C5: ='Setor CASTANHAL'!G73 -> 628 | D5: ='Setor CASTANHAL'!I73 -> 6095.62
A6: MAB | B6: =COUNT('Setor MAB'!A9:A57) -> 49 | C6: ='Setor MAB'!G58 -> 416 | D6: ='Setor MAB'!I58 -> 3633.2
A7: TOTAL PALMED | B7: =SUM(B5:B6) -> 113 | C7: =SUM(C5:C6) -> 1044 | D7: =SUM(D5:D6) -> 9728.82
A9: Mesmo distribuidor, dois setores logísticos: cada aba é um pedido/faturamento separado.

Sheet Setor CASTANHAL
A1: PEDIDO DE COMPRA — PALMED — setor CASTANHAL
A2: Cliente: | C2: DROGARIAS ROCHA
A3: Data: | C3: 20/10/2026
A4: Distribuidor: | C4: PALMED — setor CASTANHAL
A5: Condição de preço: | C5: Feirão Online Compre+ 25 anos — oferta válida 20/10 (respeitada QTD MÁX)
A6: PRAZO: | C6: Prazo de pagamento solicitado: MÍNIMO 45 DIAS — preferência até 90 DIAS (ex.: 45/60/75/90 dd ou 90 dd direto)
A8: Item | B8: Cód. distribuidor | C8: EAN | D8: Produto (descrição do distribuidor) | E8: Produto (nosso cadastro) | F8: Fabricante | G8: Qtd (cx) | H8: Preço unit. (cx) | I8: Total | J8: Cód. interno | K8: Obs.
A9: 1 | B9: 20638 | C9: 7896004817477 | D9: A SAUDE DA MULHER SOL 150ML (SALICIL+ASS | E9: A SAUDE DA MULHER SUS FR 150ML | F9: EMS MARCAS | G9: 2 | H9: 14.79 | I9: =G9*H9 -> 29.58 | J9: 356341
A10: 2 | B10: 4866 | C10: 7896004712048 | D10: TRIANC. ACETONIDA ORABASE 1MG/G POM 10G | E10: ACETONIDA DE TRIANCINOLONA 1MG POM BG 10G | F10: EMS GENERICO | G10: 14 | H10: 4.25 | I10: =G10*H10 -> 59.5 | J10: 961
A11: 3 | B11: 9787 | C11: 7896004723020 | D11: ACIDO TRANEXAMICO 250MG 12CP (GEN) | E11: ACIDO TRANEXAMICO 250MG CX 1BL X 12 COMP | F11: EMS GENERICO | G11: 18 | H11: 39.99 | I11: =G11*H11 -> 719.82 | J11: 17981
A12: 4 | B12: 1172 | C12: 7897732609259 | D12: AGUALEMA SOBRAL 200ML (TINTURA DE JALAPA | E12: AGUALEMA JALAPA 200ML | F12: SOBRAL | G12: 1 | H12: 14.99 | I12: =G12*H12 -> 14.99 | J12: 3273
A13: 5 | B13: 4754 | C13: 7896004704593 | D13: *AMOXICILINA BD 400MG/5ML 100ML SUSP+SER | E13: AMOXICILINA 400MG SUS FR 100ML | F13: EMS GENERICO | G13: 1 | H13: 19.99 | I13: =G13*H13 -> 19.99 | J13: 32521
A14: 6 | B14: 18245 | C14: 7894916341301 | D14: *AMOX+CLAV.POT. 875/125MG 20CP REV GEN | E14: AMOXICILINA+CLAVULANATO 875+125MG CX 20 COMP REV | F14: LEGRAND GENERICOS | G14: 2 | H14: 41.35 | I14: =G14*H14 -> 82.7 | J14: 109441
A15: 7 | B15: 17313 | C15: 7894916146074 | D15: ATORVASTATINA CALCICA 40MG 30CP REV (GEN | E15: ATORVASTATINA 40MG CX 3BL X 10 COMP REV | F15: LEGRAND GENERICOS | G15: 5 | H15: 13.99 | I15: =G15*H15 -> 69.95 | J15: 43681
A16: 8 | B16: 12784 | C16: 7898216360123 | D16: *AZITROPHAR 500MG 3CP (AZITROMICINA) | E16: AZITROPHAR 500MG CX 3 COM REV | F16: PHARLAB | G16: 11 | H16: 3.77 | I16: =G16*H16 -> 41.47 | J16: 48221
A17: 9 | B17: 20656 | C17: 7896004753218 | D17: BENZIFLEX LIS 125+5MG 15CP REV (LISINA+C | E17: BENZIFLEX LIS 125+5MG CX 15 COMP REV | F17: EMS MARCAS | G17: 7 | H17: 16.49 | I17: =G17*H17 -> 115.43 | J17: 134881
A18: 10 | B18: 20660 | C18: 7896004720609 | D18: BISURAN 4MG/5ML XPE INF 120ML (BROMEXIN | E18: BISURAN 4MG/5ML XPE FR 120ML INF | F18: EMS MARCAS | G18: 1 | H18: 7.49 | I18: =G18*H18 -> 7.49 | J18: 129701
A19: 11 | B19: 16325 | C19: 7896004758268 | D19: BUDESONIDA 32MCG SOL NASAL SPRAY 120ACIO | E19: BUDESONIDA 32MCG FR X 120ML | F19: EMS GENERICO | G19: 4 | H19: 15.49 | I19: =G19*H19 -> 61.96 | J19: 68701
A20: 12 | B20: 19547 | C20: 7896004731322 | D20: CARVEDILOL 25MG 30CP (GEN) | E20: CARVEDILOL 25MG 2BL X 15 COMP | F20: EMS GENERICO | G20: 4 | H20: 7.99 | I20: =G20*H20 -> 31.96 | J20: 84021
... A34: 26 | B34: 4821 | C34: 7896004711034 | D34: ESPIRONOLACTONA 50MG 30CP (GEN) | E34: ESPIRONOLACTONA 50MG CX 30 COMP | F34: EMS GENERICO | G34: 5 | H34: 15.45 | I34: =G34*H34 -> 77.25 | J34: 237021
A35: 27 | B35: 12208 | C35: 7896004812168 | D35: EXPEC XPE 120ML S/AC (OXOM+GUAI+IODE+BEN | E35: EXPEC XPE FR 120ML | F35: LEGRAND OTC | G35: 15 | H35: 20.99 | I35: =G35*H35 -> 314.85 | J35: 303461 | K35: QTD LIMITADA (ESTOQUE/Q.MÁX)
A36: 28 | B36: 12564 | C36: 7895296353014 | D36: FUCSIA FEM 3MG+0,03MG 21CP REV (DROSPI | E36: FUCSIA FEM 3+0,03MG 1BL X 21 COMP REV | F36: NOVA QUIMICA | G36: 1 | H36: 9.79 | I36: =G36*H36 -> 9.79 | J36: 239441
A37: 29 | B37: 20838 | C37: 7896004770185 | D37: GEROVITAL 30CAPS MOLE (PANAX GINSENG+ASS | E37: GEROVITAL 30 CAPSULAS MOLE | F37: EMS MARCAS | G37: 3 | H37: 36.99 | I37: =G37*H37 -> 110.97 | J37: 303521
A38: 30 | B38: 23310 | C38: 7894164009480 | D38: HIDRALI PO 28,97G 4ENV UVA | E38: HIDRALI 45 PO ENVELOPE CX C/ 4 | F38: AIRELA | G38: 2 | H38: 8.6 | I38: =G38*H38 -> 17.2 | J38: 1633
A39: 31 | B39: 18771 | C39: 7894164005406 | D39: HIDRALI SOL ORAL 500ML UVA ROXA | E39: HIDRALI 500ML UVA ROXA AIRELA | F39: AIRELA | G39: 2 | H39: 8.05 | I39: =G39*H39 -> 16.1 | J39: 531501
A40: 32 | B40: 23160 | C40: 7894164009473 | D40: HIDRALI PO 28,29G 4ENV GUARANA | E40: HIDRALI PO 28,29G ENVELOPE CX COM 4 (GUARANÁ) | F40: AIRELA | G40: 12 | H40: 8.6 | I40: =G40*H40 -> 103.2 | J40: 604151
A41: 33 | B41: 23139 | C41: 7894164009466 | D41: HIDRALI PO 28,29G 4ENV LARANJA | E41: HIDRALI PO 28,29G 4ENV LARANJA SOL | F41: AIRELA | G41: 7 | H41: 8.6 | I41: =G41*H41 -> 60.2 | J41: 602561
A42: 34 | B42: 23123 | C42: 7894164009510 | D42: HIDRALI PO SOL 28,29G 4EN NATURAL SOL | E42: HIDRALI PO NATURAL UND | F42: AIRELA | G42: 2 | H42: 8.6 | I42: =G42*H42 -> 17.2 | J42: 604091
A43: 35 | B43: 18766 | C43: 7894164005413 | D43: HIDRALI SOL ORAL 500ML GUARANA | E43: HIDRALI SABOR GUARANA 500MLFR | F43: AIRELA | G43: 4 | H43: 8.05 | I43: =G43*H43 -> 32.2 | J43: 634181
A44: 36 | B44: 17198 | C44: 7896004756721 | D44: INALAJET 32MCG SUS SPRAY NASAL 8,5ML (BU | E44: INALAJET 32MCG SUS SPR NAS | F44: LEGRAND PHARMA | G44: 6 | H44: 18.65 | I44: =G44*H44 -> 111.9 | J44: 68741
A45: 37 | B45: 588 | C45: 7896472502745 | D45: KELTRINA 5% PLUS 50MG/ML 60ML LOCAO CREM | E45: KELTRINA PLUS 5% LOCAO 60ML | F45: MULTILAB | G45: 28 | H45: 9.99 | I45: =G45*H45 -> 279.72 | J45: 403121
A46: 38 | B46: 18050 | C46: 7896004768465 | D46: LACTULIV 667MG/ML 120ML AMEIXA (LACTULOS | E46: LACTULIV 667MG/ML 120ML AMEIXA (LACTULOS | F46: MULTILAB | G46: 12 | H46: 12.85 | I46: =G46*H46 -> 154.2 | J46: 549281
A47: 39 | B47: 23932 | C47: 7894164010301 | D47: LORATADINA XPE 1MG/ML 100ML | E47: LORATADINA 1MG/ML 100ML XPE UN | F47: AIRELA | G47: 2 | H47: 5.6 | I47: =G47*H47 -> 11.2 | J47: 616271
... A65: 57 | B65: 14155 | C65: 7899620911857 | D65: SECNIDAZOL 1000MG 2CP (GEN) | E65: SECNIDAZOL 1000MG CX 2 COMP | F65: GLOBO | G65: 86 | H65: 2.49 | I65: =G65*H65 -> 214.14 | J65: 431481
A66: 58 | B66: 1385 | C66: 7898060138220 | D66: SECNIMAX 1000MG 2CP (SECNIDAZOL) | E66: SECNIMAX 1000MG CX 2 COMP | F66: GLOBO | G66: 100 | H66: 2.49 | I66: =G66*H66 -> 249 | J66: 432121 | K66: QTD LIMITADA (ESTOQUE/Q.MÁX)
A67: 59 | B67: 25344 | C67: 7894916325677 | D67: SUAVICID CREM 10G (HIDROQU+TRETI+ACETONI | E67: SUAVICID CREME 10G | F67: LEGRAND PHARMA | G67: 4 | H67: 45.85 | I67: =G67*H67 -> 183.4 | J67: 624521
A68: 60 | B68: 17240 | C68: 7896004726694 | D68: SUAVICID CREM 15G (HIDROQU+TRETI+ACETONI | E68: SUAVICID CREME BG 15G | F68: LEGRAND PHARMA | G68: 1 | H68: 57.35 | I68: =G68*H68 -> 57.35 | J68: 468821
A69: 61 | B69: 17401 | C69: 7894916149662 | D69: TADALAFILA 5MG 30CP REV (GEN) | E69: TADALAFILA 5MG CX 30 COMP REV | F69: LEGRAND GENERICOS | G69: 28 | H69: 3.49 | I69: =G69*H69 -> 97.72 | J69: 456921
A70: 62 | B70: 5944 | C70: 7899095232655 | D70: TIOCONAZOL+TINIDAZOL CREM VAG 35G+7APLIC | E70: TIOCONAZOL+TINIDAZOL 20+30MG CREME VAG 35G+7APLIC | F70: GEOLAB | G70: 1 | H70: 18.85 | I70: =G70*H70 -> 18.85 | J70: 463701
A71: 63 | B71: 19134 | C71: 7894916145541 | D71: *TOBRAMICINA SOL OFTAL 3MG/ML 5ML (GEN) | E71: TOBRAMICINA 3MG SOL OFT FR 5ML | F71: LEGRAND GENERICOS | G71: 8 | H71: 6.35 | I71: =G71*H71 -> 50.8 | J71: 464681
...

Sheet Setor MAB
A1: PEDIDO DE COMPRA — PALMED — setor MAB
A2: Cliente: | C2: DROGARIAS ROCHA
A3: Data: | C3: 20/10/2026
A4: Distribuidor: | C4: PALMED — setor MAB
A5: Condição de preço: | C5: Feirão Online Compre+ 25 anos — oferta válida 20/10 (respeitada QTD MÁX)
A6: PRAZO: | C6: Prazo de pagamento solicitado: MÍNIMO 45 DIAS — preferência até 90 DIAS (ex.: 45/60/75/90 dd ou 90 dd direto)
A8: Item | B8: Cód. distribuidor | C8: EAN | D8: Produto (descrição do distribuidor) | E8: Produto (nosso cadastro) | F8: Fabricante | G8: Qtd (cx) | H8: Preço unit. (cx) | I8: Total | J8: Cód. interno | K8: Obs.
A9: 1 | B9: 16877 | C9: 7894164008735 | D9: ABIDOR GTS 200MG/ML 15ML TUTTI-FRUT (PAR | E9: ABIDOR GTS 200MG/ML 15ML TUTTI-FRUTTI | F9: AIRELA | G9: 14 | H9: 2.39 | I9: =G9*H9 -> 33.46 | J9: 563221
A10: 2 | B10: 21522 | C10: 7899095201354 | D10: ALBEL 400MG 3CP MAST (ALBENDAZOL) | E10: ALBEL 400MG CX 03 COMP. | F10: GEOLAB | G10: 1 | H10: 3.65 | I10: =G10*H10 -> 3.65 | J10: 573221
A11: 3 | B11: 4755 | C11: 7896004719597 | D11: *AMOX+CLAV.POT. 875/125MG 14CP REV (GEN) | E11: AMOXICILINA+CLAV POTASSIO 875+125MG CX 14 COMP REV | F11: EMS GENERICO | G11: 4 | H11: 41.75 | I11: =G11*H11 -> 167 | J11: 109341
A12: 4 | B12: 12015 | C12: 7899620910584 | D12: APETISINA BC UVA 240ML (VITAMINAS A+C+M | E12: APETISINA BC 240ML UVA | F12: GLOBO | G12: 1 | H12: 5.29 | I12: =G12*H12 -> 5.29 | J12: 547741
A13: 5 | B13: 12391 | C13: 7896004705781 | D13: ATENOLOL 25MG 30CP (GEN) | E13: ATENOLOL 25MG CX 30 COMP | F13: EMS GENERICO | G13: 4 | H13: 2.25 | I13: =G13*H13 -> 9 | J13: 39481
A14: 6 | B14: 17923 | C14: 7898216365708 | D14: *AZITROMICINA DI-HIDRATADA 500MG 5CP REV | E14: AZITROMICINA DI-HIDRATADA 500MG CX 5 COMP REV | F14: PHARLAB | G14: 15 | H14: 5.79 | I14: =G14*H14 -> 86.85 | J14: 47221
A15: 7 | B15: 6310 | C15: 7898216364510 | D15: *AZITROPHAR 200MG/5ML 600MG PO SUSP+SER | E15: AZITROPHAR 600MG PO SUS OR FR 15ML + SER DOS 5ML | F15: PHARLAB | G15: 3 | H15: 13.92 | I15: =G15*H15 -> 41.76 | J15: 47701
A16: 8 | B16: 5935 | C16: 7899095204430 | D16: *BETOGENTA POM 30G (BETAMET+GENTAMICINA) | E16: BETOGENTA 0,5+1,0MG POM BG 30G | F16: GEOLAB | G16: 3 | H16: 7.8 | I16: =G16*H16 -> 23.4 | J16: 449241
A17: 9 | B17: 24760 | C17: 7891317017002 | D17: CILOSTAZOL 50MG 30CP (GEN) | E17: CILOSTAZOL 50MG CX 30 COMP | F17: EUROFARMA | G17: 5 | H17: 9.99 | I17: =G17*H17 -> 49.95 | J17: 619051
A18: 10 | B18: 15305 | C18: 7899095202412 | D18: #CLONAZEPAM (B1) GTS 2,5MG/ML 20ML (GEN) | E18: CLONAZEPAM 2,5M/ML SOL OR FR GOT 20ML | F18: GEOLAB | G18: 2 | H18: 4.8 | I18: =G18*H18 -> 9.6 | J18: 112501
A19: 11 | B19: 10560 | C19: 7898060131504 | D19: BROMEXINA AD 120ML 8MG/5ML (GEN) | E19: CLORIDRATO DE BROMEXINA 1,6MG XPE FR 120ML+CM | F19: GLOBO | G19: 2 | H19: 6.49 | I19: =G19*H19 -> 12.98 | J19: 129761
A20: 12 | B20: 23394 | C20: 7898060139951 | D20: CICLOBENZAPRINA 10MG 30CP REV (GEN) | E20: CLORIDRATO DE CICLOBENZAPRINA 10MG CX 30 COMP REV | F20: GLOBO | G20: 2 | H20: 4.89 | I20: =G20*H20 -> 9.78 | J20: 134601
... A45: 37 | B45: 13069 | C45: 7899095221284 | D45: RESFRILIV 50ENV 5G SABOR HORTELA+GENGIBR | E45: RESFRILIV 400+4+4MG CX 50 ENV SB HORTELA/GENGIBRE | F45: GEOLAB | G45: 1 | H45: 43.99 | I45: =G45*H45 -> 43.99 | J45: 146101
A46: 38 | B46: 13652 | C46: 7898133134784 | D46: *RIFOTRAT SPRAY 10MG/ML 20ML (RIFAMICINA | E46: RIFOTRAT 10 MG/ML SOL TOP SPRAY CT FR PLAS AMB X 20 ML | F46: NATULAB LABORATORIO | G46: 40 | H46: 6.99 | I46: =G46*H46 -> 279.6 | J46: 418201 | K46: QTD LIMITADA (ESTOQUE/Q.MÁX)
A47: 39 | B47: 5323 | C47: 7896004729640 | D47: ROSUVASTATINA CALCICA 10MG 30CP REV (GEN | E47: ROSUVASTATINA CALCICA 10MG CX 3BL X 10 COMP REV | F47: EMS GENERICO | G47: 20 | H47: 7.49 | I47: =G47*H47 -> 149.8 | J47: 427761
A48: 40 | B48: 22649 | C48: 7899898601788 | D48: SEAKALM MELATONINA SOL ORAL 15ML | E48: SEAKALM MELATONINA 0,21MG 15ML GTS | F48: NATULAB LABORATORIO | G48: 6 | H48: 7.89 | I48: =G48*H48 -> 47.34 | J48: 636781
A49: 41 | B49: 3767 | C49: 7898060132730 | D49: SINTAFLAT 40MG 20CP (SIMETICONA) | E49: SINTAFLAT (N.S.) 40MG CX 20 COMP | F49: GLOBO | G49: 7 | H49: 2.99 | I49: =G49*H49 -> 20.93 | J49: 219981
A50: 42 | B50: 15756 | C50: 7899620911079 | D50: SINVASTATINA 40MG 30CP REV (GEN) | E50: SINVASTATINA 40MG CX 30 COMP REV | F50: GLOBO | G50: 2 | H50: 5.89 | I50: =G50*H50 -> 11.78 | J50: 436201
A51: 43 | B51: 18134 | C51: 7894164005802 | D51: SULFERMAX GTS 30ML (SULFATO FERROSO) | E51: SULFERMAX GTS 30ML (SULFATO FERROSO) | F51: AIRELA INDUSTRIA FARMACEUTICA | G51: 14 | H51: 3.15 | I51: =G51*H51 -> 44.1 | J51: 612291
A52: 44 | B52: 13061 | C52: 7893454100715 | D52: TIADOL POM 50MG/G 20G (TIABENDAZOL) | E52: TIADOL 50MG/G POM DERM BG 20G | F52: CELLERA FARMA | G52: 1 | H52: 13.37 | I52: =G52*H52 -> 13.37 | J52: 461941
A53: 45 | B53: 11746 | C53: 7899095201378 | D53: TRAXONOL 100MG 15CAPS (ITRACONAZOL) | E53: TRAXONOL 100MG CX 15 CAP | F53: GEOLAB | G53: 12 | H53: 13.99 | I53: =G53*H53 -> 167.88 | J53: 306961 | K53: QTD LIMITADA (ESTOQUE/Q.MÁX)
A54: 46 | B54: 10559 | C54: 7899095200296 | D54: TRAXONOL 100MG 4CAPS (ITRACONAZOL | E54: TRAXONOL 100MG CX 4 CAP | F54: GEOLAB | G54: 4 | H54: 6.35 | I54: =G54*H54 -> 25.4 | J54: 306941
A55: 47 | B55: 15596 | C55: 7898593050488 | D55: VITAMINA B12 60CAPS (SUPLEMENTO VITAMIN | E55: VITAMINA B-12 100% IDR C/60 CAFR | F55: PADRAO | G55: 14 | H55: 18.55 | I55: =G55*H55 -> 259.7 | J55: 562761
A56: 48 | B56: 16882 | C56: 7894164001132 | D56: VITAXON C 1G 10CP EFERV LARANJA (ACIDO A | E56: VITAXON C 1G EFERV LARANJA CX C 10 EFER | F56: AIRELA | G56: 80 | H56: 3.79 | I56: =G56*H56 -> 303.2 | J56: 532021 | K56: QTD LIMITADA (ESTOQUE/Q.MÁX)
A57: 49 | B57: 12352 | C57: 7899470802961 | D57: XAROPE DE GUACO 100ML MEL MENTOL S/ACUCA | E57: XAROPE DE GUACO 120ML | F57: NATULAB LABORATORIO | G57: 5 | H57: 6.09 | I57: =G57*H57 -> 30.45 | J57: 555181
D58: TOTAL | F58: =COUNT(A9:A57)&" itens" -> 49 itens | G58: =SUM(G9:G57) -> 416 | I58: =SUM(I9:I57) -> 3633.2
A60: Observações:
A61: • Prazo de pagamento solicitado: MÍNIMO 45 DIAS — preferência até 90 DIAS (ex.: 45/60/75/90 dd ou 90 dd direto)
A62: • Quantidades em CAIXAS fechadas (não comprar fração).
A63: • Preços conforme oferta vigente em 20/10/2026. Favor confirmar preço, prazo e disponibilidade antes do faturamento.
A64: • Itens sem estoque total: faturar o disponível e informar o saldo.
