Workbook

Sheet Resumo
A1: RESUMO DA COTAÇÃO — 20/10/2026 (PARCIAL)
A2: DIMEC x MEDCENTRO por EAN. Palmed (CAST/MAB) entra após correlação. Regra: não comprar com reajuste > limite (Premissas).
A3: Indicador | B3: Valor
A4: Itens na Lista de Compra | B4: =COUNTA(Cotação!$C$6:$C$5941) -> 5936
A5: Valor da lista (Qtd sugerida × preço ref.) | B5: =SUMPRODUCT(Cotação!$I$6:$I$5941,Cotação!$M$6:$M$5941) -> 464600.39
A6: Itens com ao menos 1 oferta | B6: =COUNTIF(Cotação!$AA$6:$AA$5941,"<>SEM OFERTA") -> 1096
A7: Itens SEM oferta | B7: =COUNTIF(Cotação!$AA$6:$AA$5941,"SEM OFERTA") -> 4840
A8: Itens a COMPRAR | B8: =COUNTIF(Cotação!$AA$6:$AA$5941,"COMPRAR") -> 576
A9: Itens bloqueados (reajuste > limite) | B9: =COUNTIF(Cotação!$AA$6:$AA$5941,"NÃO*") -> 504
A10: Itens p/ verificar unidade/embalagem | B10: =COUNTIF(Cotação!$AA$6:$AA$5941,"VERIFICAR*") -> 16
A11: Valor total do pedido | B11: =SUM(Cotação!$AD$6:$AD$5941) -> 35018.49
A12: Mesmos itens ao preço de referência | B12: =SUMPRODUCT((Cotação!$AA$6:$AA$5941="COMPRAR")*Cotação!$AC$6:$AC$5941*Cotação!$M$6:$M$5941) -> 35665.449
A13: Economia total vs. referência | B13: =SUM(Cotação!$AE$6:$AE$5941) -> 646.95848
A14: Economia % | B14: =IFERROR(B13/B12,0) -> 0.018139642
A15: Itens com estoque insuficiente no vencedor | B15: =COUNTIF(Cotação!$AF$6:$AF$5941,"ESTOQUE INSUFICIENTE") -> 30
A16: Itens em empate técnico (dif. < R$0,01) | B16: =COUNTIF(Cotação!$AF$6:$AF$5941,"EMPATE TÉCNICO") -> 4
A18: PEDIDO POR DISTRIBUIDOR
A19: Distribuidor | B19: Itens vencedores | C19: Itens a comprar | D19: Caixas | E19: Valor pedido | F19: Economia vs ref. | G19: % do pedido | H19: Itens bloqueados (>5%)
A20: DIMEC | B20: =COUNTIF(Cotação!$W$6:$W$5941,A20) -> 598 | C20: =COUNTIFS(Cotação!$W$6:$W$5941,A20,Cotação!$AA$6:$AA$5941,"COMPRAR") -> 292 | D20: =SUMIFS(Cotação!$AC$6:$AC$5941,Cotação!$W$6:$W$5941,A20) -> 3492 | E20: =SUMIFS(Cotação!$AD$6:$AD$5941,Cotação!$W$6:$W$5941,A20) -> 17429.269 | F20: =SUMIFS(Cotação!$AE$6:$AE$5941,Cotação!$W$6:$W$5941,A20) -> 500.75131 | G20: =IFERROR(E20/$E$24,0) -> 0.49771616 | H20: =COUNTIFS(Cotação!$W$6:$W$5941,A20,Cotação!$AA$6:$AA$5941,"NÃO*") -> 293
A21: MEDCENTRO | B21: =COUNTIF(Cotação!$W$6:$W$5941,A21) -> 498 | C21: =COUNTIFS(Cotação!$W$6:$W$5941,A21,Cotação!$AA$6:$AA$5941,"COMPRAR") -> 284 | D21: =SUMIFS(Cotação!$AC$6:$AC$5941,Cotação!$W$6:$W$5941,A21) -> 2088 | E21: =SUMIFS(Cotação!$AD$6:$AD$5941,Cotação!$W$6:$W$5941,A21) -> 17589.221 | F21: =SUMIFS(Cotação!$AE$6:$AE$5941,Cotação!$W$6:$W$5941,A21) -> 146.20716 | G21: =IFERROR(E21/$E$24,0) -> 0.50228384 | H21: =COUNTIFS(Cotação!$W$6:$W$5941,A21,Cotação!$AA$6:$AA$5941,"NÃO*") -> 211
A22: PALMED CAST | B22: =COUNTIF(Cotação!$W$6:$W$5941,A22) -> 0 | C22: =COUNTIFS(Cotação!$W$6:$W$5941,A22,Cotação!$AA$6:$AA$5941,"COMPRAR") -> 0 | D22: =SUMIFS(Cotação!$AC$6:$AC$5941,Cotação!$W$6:$W$5941,A22) -> 0 | E22: =SUMIFS(Cotação!$AD$6:$AD$5941,Cotação!$W$6:$W$5941,A22) -> 0 | F22: =SUMIFS(Cotação!$AE$6:$AE$5941,Cotação!$W$6:$W$5941,A22) -> 0 | G22: =IFERROR(E22/$E$24,0) -> 0 | H22: =COUNTIFS(Cotação!$W$6:$W$5941,A22,Cotação!$AA$6:$AA$5941,"NÃO*") -> 0
A23: PALMED MAB | B23: =COUNTIF(Cotação!$W$6:$W$5941,A23) -> 0 | C23: =COUNTIFS(Cotação!$W$6:$W$5941,A23,Cotação!$AA$6:$AA$5941,"COMPRAR") -> 0 | D23: =SUMIFS(Cotação!$AC$6:$AC$5941,Cotação!$W$6:$W$5941,A23) -> 0 | E23: =SUMIFS(Cotação!$AD$6:$AD$5941,Cotação!$W$6:$W$5941,A23) -> 0 | F23: =SUMIFS(Cotação!$AE$6:$AE$5941,Cotação!$W$6:$W$5941,A23) -> 0 | G23: =IFERROR(E23/$E$24,0) -> 0 | H23: =COUNTIFS(Cotação!$W$6:$W$5941,A23,Cotação!$AA$6:$AA$5941,"NÃO*") -> 0
A24: TOTAL | B24: =SUM(B20:B23) -> 1096 | C24: =SUM(C20:C23) -> 576 | D24: =SUM(D20:D23) -> 5580 | E24: =SUM(E20:E23) -> 35018.49 | F24: =SUM(F20:F23) -> 646.95848 | G24: =SUM(G20:G23) -> 1 | H24: =SUM(H20:H23) -> 504
A27: DIMEC x MEDCENTRO — itens ofertados pelos dois
A28: Itens com preço nos dois | B28: =SUMPRODUCT((Cotação!$N$6:$N$5941<>"")*(Cotação!$R$6:$R$5941<>"")) -> 364
A29: DIMEC mais barata | B29: =SUMPRODUCT((Cotação!$N$6:$N$5941<>"")*(Cotação!$R$6:$R$5941<>"")*(Cotação!$N$6:$N$5941<Cotação!$O$6:$O$5941)) -> 175
A30: MEDCENTRO mais barata (já c/ desconto) | B30: =SUMPRODUCT((Cotação!$N$6:$N$5941<>"")*(Cotação!$R$6:$R$5941<>"")*(Cotação!$O$6:$O$5941<Cotação!$N$6:$N$5941)) -> 189
A31: Empate | B31: =B28-B29-B30 -> 0
A34: POR CURVA ABC
A35: Curva | B35: Itens lista | C35: Itens a comprar | D35: Bloqueados >5% | E35: Valor pedido | F35: Economia
A36: A | B36: =COUNTIF(Cotação!$F$6:$F$5941,A36) -> 1448 | C36: =COUNTIFS(Cotação!$F$6:$F$5941,A36,Cotação!$AA$6:$AA$5941,"COMPRAR") -> 192 | D36: =COUNTIFS(Cotação!$F$6:$F$5941,A36,Cotação!$AA$6:$AA$5941,"NÃO*") -> 160 | E36: =SUMIFS(Cotação!$AD$6:$AD$5941,Cotação!$F$6:$F$5941,A36) -> 23312.359 | F36: =SUMIFS(Cotação!$AE$6:$AE$5941,Cotação!$F$6:$F$5941,A36) -> 401.46352
A37: B | B37: =COUNTIF(Cotação!$F$6:$F$5941,A37) -> 1241 | C37: =COUNTIFS(Cotação!$F$6:$F$5941,A37,Cotação!$AA$6:$AA$5941,"COMPRAR") -> 189 | D37: =COUNTIFS(Cotação!$F$6:$F$5941,A37,Cotação!$AA$6:$AA$5941,"NÃO*") -> 126 | E37: =SUMIFS(Cotação!$AD$6:$AD$5941,Cotação!$F$6:$F$5941,A37) -> 8242.9571 | F37: =SUMIFS(Cotação!$AE$6:$AE$5941,Cotação!$F$6:$F$5941,A37) -> 66.478426
A38: C | B38: =COUNTIF(Cotação!$F$6:$F$5941,A38) -> 3247 | C38: =COUNTIFS(Cotação!$F$6:$F$5941,A38,Cotação!$AA$6:$AA$5941,"COMPRAR") -> 195 | D38: =COUNTIFS(Cotação!$F$6:$F$5941,A38,Cotação!$AA$6:$AA$5941,"NÃO*") -> 218 | E38: =SUMIFS(Cotação!$AD$6:$AD$5941,Cotação!$F$6:$F$5941,A38) -> 3463.1737 | F38: =SUMIFS(Cotação!$AE$6:$AE$5941,Cotação!$F$6:$F$5941,A38) -> 179.01653
A44: PALMED — CAST x MAB (encarte, antes da correlação)
A45: Códigos no encarte (únicos) | B45: =COUNTA('Palmed CAST x MAB'!A4:A829) -> 826
A46: Só CAST | B46: =COUNTIFS('Palmed CAST x MAB'!E4:E829,"<>",'Palmed CAST x MAB'!H4:H829,"") -> 183
A47: Só MAB | B47: =COUNTIFS('Palmed CAST x MAB'!H4:H829,"<>",'Palmed CAST x MAB'!E4:E829,"") -> 238
A48: Nos dois setores | B48: =COUNT('Palmed CAST x MAB'!L4:L829) -> 405
A49: CAST mais barato | B49: =COUNTIF('Palmed CAST x MAB'!L4:L829,"<0") -> 87
A50: MAB mais barato | B50: =COUNTIF('Palmed CAST x MAB'!L4:L829,">0") -> 104
...

Sheet Cotação
A1: COTAÇÃO — Drogarias Rocha — 20/10/2026 (PARCIAL: DIMEC x MEDCENTRO; Palmed aguardando correlação)
A2: Casamento por EAN. MEDCENTRO com desconto adicional e limite de reajuste definidos na aba Premissas.
N4: DIMEC | O4: MEDCENTRO | P4: PALMED CAST | Q4: PALMED MAB
A5: Cód. interno | B5: EAN | C5: Produto | D5: Fabricante | E5: Un/Cx | F5: ABC | G5: Est. rede (un) | H5: Dem./mês (un) | I5: Qtd sugerida (cx) | J5: Últ. preço compra (un) | K5: Custo un (lista) | L5: Melhor 3m (un) | M5: Preço ref. (CAIXA) | N5: DIMEC | O5: MEDCENTRO (líq. -5%) | P5: PALMED CAST | Q5: PALMED MAB | R5: MEDC tabela | S5: DIMEC estoque | T5: DIMEC un/cx | U5: MEDC estoque | V5: Melhor preço (cx) | W5: Vencedor | X5: 2º melhor preço | Y5: Var. vs ref. | Z5: Var. vs melhor 3m | AA5: Decisão | AB5: Estoque vencedor | AC5: Qtd pedido (cx) | AD5: Valor pedido | AE5: Economia vs ref. | AF5: Alerta | AG5: Últ. fornecedor | AH5: Grupo
A6: 550941 | B6: 7894488000101 | C6: FLOCONETES SEGUROS E ABSORVENTES 75UN | D6: SPARTEX IND. | E6: 1 | F6: C | G6: 1 | H6: 0.6 | I6: 1 | J6: 1.35 | K6: 1.35 | L6: 1.35 | M6: =IF(J6>0,J6,K6)*E6 -> 1.35 | N6: 1.35 | O6: =IF(R6="","",ROUND(R6*(1-Premissas!$B$4),4)) | S6: 1677 | T6: 12 | V6: =IF(COUNT(N6:Q6)=0,"",MIN(N6:Q6)) -> 1.35 | W6: =IF(V6="","",INDEX($N$4:$Q$4,MATCH(V6,N6:Q6,0))) -> DIMEC | X6: =IF(COUNT(N6:Q6)<2,"",SMALL(N6:Q6,2)) | Y6: =IF(OR(V6="",M6=0),"",V6/M6-1) -> 0 | Z6: =IF(OR(V6="",L6=""),"",V6/(L6*E6)-1) -> 0 | AA6: =IF(V6="","SEM OFERTA",IF(OR(Y6>Premissas!$B$11,Y6<Premissas!$B$12),"VERIFICAR - UNIDADE/EMBALAGEM",IF(Y6>Premissas!$B$6,"NÃO COMPRAR - REAJUSTE >5%","COMPRAR"))) -> COMPRAR | AB6: =IF(W6="DIMEC",S6,IF(W6="MEDCENTRO",U6,"")) -> 1677 | AC6: =IF(AA6<>"COMPRAR",0,IF(AB6="",I6,MIN(I6,AB6))) -> 1 | AD6: =IF(AC6>0,AC6*V6,0) -> 1.35 | AE6: =IF(AC6>0,(M6-V6)*AC6,0) -> 0 | AF6: =IF(AA6<>"COMPRAR","",IF(AB6="",IF(X6="","",IF(X6-V6<0.01,"EMPATE TÉCNICO","")),IF(AB6<I6,"ESTOQUE INSUFICIENTE",IF(X6="","",IF(X6-V6<0.01,"EMPATE TÉCNICO",""))))) | AG6: JLCS COMERCIO E DISTRIBUICAO DE ALIMENTO LTDA | AH6: ABSORVENTES
A7: 643491 | B7: 7896699032520 | C7: 1560-01-F MAM TIP 80ML SIL R F CX C/6 - LOLLY | D7: LOLLY | E7: 1 | F7: B | G7: 1 | H7: 0.5 | I7: 1 | J7: 12.8 | K7: 12.8 | L7: 12.8 | M7: =IF(J7>0,J7,K7)*E7 -> 12.8 | O7: =IF(R7="","",ROUND(R7*(1-Premissas!$B$4),4)) -> 12.3215 | R7: 12.97 | U7: 78 | V7: =IF(COUNT(N7:Q7)=0,"",MIN(N7:Q7)) -> 12.3215 | W7: =IF(V7="","",INDEX($N$4:$Q$4,MATCH(V7,N7:Q7,0))) -> MEDCENTRO | X7: =IF(COUNT(N7:Q7)<2,"",SMALL(N7:Q7,2)) | Y7: =IF(OR(V7="",M7=0),"",V7/M7-1) -> -0.037382813 | Z7: =IF(OR(V7="",L7=""),"",V7/(L7*E7)-1) -> -0.037382813 | AA7: =IF(V7="","SEM OFERTA",IF(OR(Y7>Premissas!$B$11,Y7<Premissas!$B$12),"VERIFICAR - UNIDADE/EMBALAGEM",IF(Y7>Premissas!$B$6,"NÃO COMPRAR - REAJUSTE >5%","COMPRAR"))) -> COMPRAR | AB7: =IF(W7="DIMEC",S7,IF(W7="MEDCENTRO",U7,"")) -> 78 | AC7: =IF(AA7<>"COMPRAR",0,IF(AB7="",I7,MIN(I7,AB7))) -> 1 | AD7: =IF(AC7>0,AC7*V7,0) -> 12.3215 | AE7: =IF(AC7>0,(M7-V7)*AC7,0) -> 0.4785 | AF7: =IF(AA7<>"COMPRAR","",IF(AB7="",IF(X7="","",IF(X7-V7<0.01,"EMPATE TÉCNICO","")),IF(AB7<I7,"ESTOQUE INSUFICIENTE",IF(X7="","",IF(X7-V7<0.01,"EMPATE TÉCNICO",""))))) | AG7: BATEL COMERCIO DE ALIMENTOS LTDA | AH7: BABY/KIDS
A8: 643501 | B8: 7896699032537 | C8: 1560-01-M MAM TIP 80ML SIL R M LOLLY | D8: LOLLY | E8: 1 | F8: C | G8: 2 | H8: 0.8 | I8: 1 | J8: 12.8 | K8: 12.8 | L8: 12.26 | M8: =IF(J8>0,J8,K8)*E8 -> 12.8 | O8: =IF(R8="","",ROUND(R8*(1-Premissas!$B$4),4)) -> 12.3215 | R8: 12.97 | U8: 29 | V8: =IF(COUNT(N8:Q8)=0,"",MIN(N8:Q8)) -> 12.3215 | W8: =IF(V8="","",INDEX($N$4:$Q$4,MATCH(V8,N8:Q8,0))) -> MEDCENTRO | X8: =IF(COUNT(N8:Q8)<2,"",SMALL(N8:Q8,2)) | Y8: =IF(OR(V8="",M8=0),"",V8/M8-1) -> -0.037382813 | Z8: =IF(OR(V8="",L8=""),"",V8/(L8*E8)-1) -> 0.0050163132 | AA8: =IF(V8="","SEM OFERTA",IF(OR(Y8>Premissas!$B$11,Y8<Premissas!$B$12),"VERIFICAR - UNIDADE/EMBALAGEM",IF(Y8>Premissas!$B$6,"NÃO COMPRAR - REAJUSTE >5%","COMPRAR"))) -> COMPRAR | AB8: =IF(W8="DIMEC",S8,IF(W8="MEDCENTRO",U8,"")) -> 29 | AC8: =IF(AA8<>"COMPRAR",0,IF(AB8="",I8,MIN(I8,AB8))) -> 1 | AD8: =IF(AC8>0,AC8*V8,0) -> 12.3215 | AE8: =IF(AC8>0,(M8-V8)*AC8,0) -> 0.4785 | AF8: =IF(AA8<>"COMPRAR","",IF(AB8="",IF(X8="","",IF(X8-V8<0.01,"EMPATE TÉCNICO","")),IF(AB8<I8,"ESTOQUE INSUFICIENTE",IF(X8="","",IF(X8-V8<0.01,"EMPATE TÉCNICO",""))))) | AG8: BATEL COMERCIO DE ALIMENTOS LTDA | AH8: BABY/KIDS
A9: 643511 | B9: 7896699015479 | C9: 1970-01-F MINI MAM CLEAN 50ML F - LOLLY | D9: LOLLY | E9: 1 | F9: B | G9: 1 | H9: 4.3 | I9: 11 | J9: 9.07 | K9: 9.07 | L9: 9.07 | M9: =IF(J9>0,J9,K9)*E9 -> 9.07 | O9: =IF(R9="","",ROUND(R9*(1-Premissas!$B$4),4)) -> 9.12 | R9: 9.6 | U9: 333 | V9: =IF(COUNT(N9:Q9)=0,"",MIN(N9:Q9)) -> 9.12 | W9: =IF(V9="","",INDEX($N$4:$Q$4,MATCH(V9,N9:Q9,0))) -> MEDCENTRO | X9: =IF(COUNT(N9:Q9)<2,"",SMALL(N9:Q9,2)) | Y9: =IF(OR(V9="",M9=0),"",V9/M9-1) -> 0.0055126792 | Z9: =IF(OR(V9="",L9=""),"",V9/(L9*E9)-1) -> 0.0055126792 | AA9: =IF(V9="","SEM OFERTA",IF(OR(Y9>Premissas!$B$11,Y9<Premissas!$B$12),"VERIFICAR - UNIDADE/EMBALAGEM",IF(Y9>Premissas!$B$6,"NÃO COMPRAR - REAJUSTE >5%","COMPRAR"))) -> COMPRAR | AB9: =IF(W9="DIMEC",S9,IF(W9="MEDCENTRO",U9,"")) -> 333 | AC9: =IF(AA9<>"COMPRAR",0,IF(AB9="",I9,MIN(I9,AB9))) -> 11 | AD9: =IF(AC9>0,AC9*V9,0) -> 100.32 | AE9: =IF(AC9>0,(M9-V9)*AC9,0) -> -0.55 | AF9: =IF(AA9<>"COMPRAR","",IF(AB9="",IF(X9="","",IF(X9-V9<0.01,"EMPATE TÉCNICO","")),IF(AB9<I9,"ESTOQUE INSUFICIENTE",IF(X9="","",IF(X9-V9<0.01,"EMPATE TÉCNICO",""))))) | AG9: BATEL COMERCIO DE ALIMENTOS LTDA | AH9: BABY/KIDS
A10: 643521 | B10: 7896699015455 | C10: 1970-01-M MINI MAM CLEAN 50ML M CX C/6 - LOLLY | D10: LOLLY | E10: 1 | F10: B | G10: 0 | H10: 2.1 | I10: 6 | J10: 9.07 | K10: 9.07 | L10: 9.07 | M10: =IF(J10>0,J10,K10)*E10 -> 9.07 | O10: =IF(R10="","",ROUND(R10*(1-Premissas!$B$4),4)) -> 9.12 | R10: 9.6 | U10: 250 | V10: =IF(COUNT(N10:Q10)=0,"",MIN(N10:Q10)) -> 9.12 | W10: =IF(V10="","",INDEX($N$4:$Q$4,MATCH(V10,N10:Q10,0))) -> MEDCENTRO | X10: =IF(COUNT(N10:Q10)<2,"",SMALL(N10:Q10,2)) | Y10: =IF(OR(V10="",M10=0),"",V10/M10-1) -> 0.0055126792 | Z10: =IF(OR(V10="",L10=""),"",V10/(L10*E10)-1) -> 0.0055126792 | AA10: =IF(V10="","SEM OFERTA",IF(OR(Y10>Premissas!$B$11,Y10<Premissas!$B$12),"VERIFICAR - UNIDADE/EMBALAGEM",IF(Y10>Premissas!$B$6,"NÃO COMPRAR - REAJUSTE >5%","COMPRAR"))) -> COMPRAR | AB10: =IF(W10="DIMEC",S10,IF(W10="MEDCENTRO",U10,"")) -> 250 | AC10: =IF(AA10<>"COMPRAR",0,IF(AB10="",I10,MIN(I10,AB10))) -> 6 | AD10: =IF(AC10>0,AC10*V10,0) -> 54.72 | AE10: =IF(AC10>0,(M10-V10)*AC10,0) -> -0.3 | AF10: =IF(AA10<>"COMPRAR","",IF(AB10="",IF(X10="","",IF(X10-V10<0.01,"EMPATE TÉCNICO","")),IF(AB10<I10,"ESTOQUE INSUFICIENTE",IF(X10="","",IF(X10-V10<0.01,"EMPATE TÉCNICO",""))))) | AG10: BATEL COMERCIO DE ALIMENTOS LTDA | AH10: BABY/KIDS
A11: 643541 | B11: 7896699019217 | C11: 3262-01-F MAM TRICOLOR 250ML SIL O F CX/6 - LOLLY | D11: LOLLY | E11: 1 | F11: B | G11: 1 | H11: 0.5 | I11: 1 | J11: 13.71 | K11: 13.71 | L11: 13.71 | M11: =IF(J11>0,J11,K11)*E11 -> 13.71 | O11: =IF(R11="","",ROUND(R11*(1-Premissas!$B$4),4)) -> 19.7695 | R11: 20.81 | U11: 6 | V11: =IF(COUNT(N11:Q11)=0,"",MIN(N11:Q11)) -> 19.7695 | W11: =IF(V11="","",INDEX($N$4:$Q$4,MATCH(V11,N11:Q11,0))) -> MEDCENTRO | X11: =IF(COUNT(N11:Q11)<2,"",SMALL(N11:Q11,2)) | Y11: =IF(OR(V11="",M11=0),"",V11/M11-1) -> 0.44197666 | Z11: =IF(OR(V11="",L11=""),"",V11/(L11*E11)-1) -> 0.44197666 | AA11: =IF(V11="","SEM OFERTA",IF(OR(Y11>Premissas!$B$11,Y11<Premissas!$B$12),"VERIFICAR - UNIDADE/EMBALAGEM",IF(Y11>Premissas!$B$6,"NÃO COMPRAR - REAJUSTE >5%","COMPRAR"))) -> NÃO COMPRAR - REAJUSTE >5% | AB11: =IF(W11="DIMEC",S11,IF(W11="MEDCENTRO",U11,"")) -> 6 | AC11: =IF(AA11<>"COMPRAR",0,IF(AB11="",I11,MIN(I11,AB11))) -> 0 | AD11: =IF(AC11>0,AC11*V11,0) -> 0 | AE11: =IF(AC11>0,(M11-V11)*AC11,0) -> 0 | AF11: =IF(AA11<>"COMPRAR","",IF(AB11="",IF(X11="","",IF(X11-V11<0.01,"EMPATE TÉCNICO","")),IF(AB11<I11,"ESTOQUE INSUFICIENTE",IF(X11="","",IF(X11-V11<0.01,"EMPATE TÉCNICO",""))))) | AG11: BATEL COMERCIO DE ALIMENTOS LTDA | AH11: BABY/KIDS
A12: 643571 | B12: 7896699022330 | C12: 4512-01-N CH BORBOLETA SIL R T2 N - LOLLY | D12: LOLLY | E12: 1 | F12: C | G12: 1 | H12: 1.2 | I12: 2 | J12: 6.8 | K12: 6.8 | L12: 6.8 | M12: =IF(J12>0,J12,K12)*E12 -> 6.8 | O12: =IF(R12="","",ROUND(R12*(1-Premissas!$B$4),4)) -> 8.056 | R12: 8.48 | U12: 28 | V12: =IF(COUNT(N12:Q12)=0,"",MIN(N12:Q12)) -> 8.056 | W12: =IF(V12="","",INDEX($N$4:$Q$4,MATCH(V12,N12:Q12,0))) -> MEDCENTRO | X12: =IF(COUNT(N12:Q12)<2,"",SMALL(N12:Q12,2)) | Y12: =IF(OR(V12="",M12=0),"",V12/M12-1) -> 0.18470588 | Z12: =IF(OR(V12="",L12=""),"",V12/(L12*E12)-1) -> 0.18470588 | AA12: =IF(V12="","SEM OFERTA",IF(OR(Y12>Premissas!$B$11,Y12<Premissas!$B$12),"VERIFICAR - UNIDADE/EMBALAGEM",IF(Y12>Premissas!$B$6,"NÃO COMPRAR - REAJUSTE >5%","COMPRAR"))) -> NÃO COMPRAR - REAJUSTE >5% | AB12: =IF(W12="DIMEC",S12,IF(W12="MEDCENTRO",U12,"")) -> 28 | AC12: =IF(AA12<>"COMPRAR",0,IF(AB12="",I12,MIN(I12,AB12))) -> 0 | AD12: =IF(AC12>0,AC12*V12,0) -> 0 | AE12: =IF(AC12>0,(M12-V12)*AC12,0) -> 0 | AF12: =IF(AA12<>"COMPRAR","",IF(AB12="",IF(X12="","",IF(X12-V12<0.01,"EMPATE TÉCNICO","")),IF(AB12<I12,"ESTOQUE INSUFICIENTE",IF(X12="","",IF(X12-V12<0.01,"EMPATE TÉCNICO",""))))) | AG12: BATEL COMERCIO DE ALIMENTOS LTDA | AH12: BABY/KIDS
A13: 643581 | B13: 7896699022484 | C13: 4515-01-F CH TIP BORBOLETA SIL O T2 F CX/6 - LOLLY | D13: LOLLY | E13: 1 | F13: C | G13: 1 | H13: 1.4 | I13: 3 | J13: 7.25 | K13: 7.25 | L13: 7.25 | M13: =IF(J13>0,J13,K13)*E13 -> 7.25 | O13: =IF(R13="","",ROUND(R13*(1-Premissas!$B$4),4)) -> 8.056 | R13: 8.48 | U13: 140 | V13: =IF(COUNT(N13:Q13)=0,"",MIN(N13:Q13)) -> 8.056 | W13: =IF(V13="","",INDEX($N$4:$Q$4,MATCH(V13,N13:Q13,0))) -> MEDCENTRO | X13: =IF(COUNT(N13:Q13)<2,"",SMALL(N13:Q13,2)) | Y13: =IF(OR(V13="",M13=0),"",V13/M13-1) -> 0.11117241 | Z13: =IF(OR(V13="",L13=""),"",V13/(L13*E13)-1) -> 0.11117241 | AA13: =IF(V13="","SEM OFERTA",IF(OR(Y13>Premissas!$B$11,Y13<Premissas!$B$12),"VERIFICAR - UNIDADE/EMBALAGEM",IF(Y13>Premissas!$B$6,"NÃO COMPRAR - REAJUSTE >5%","COMPRAR"))) -> NÃO COMPRAR - REAJUSTE >5% | AB13: =IF(W13="DIMEC",S13,IF(W13="MEDCENTRO",U13,"")) -> 140 | AC13: =IF(AA13<>"COMPRAR",0,IF(AB13="",I13,MIN(I13,AB13))) -> 0 | AD13: =IF(AC13>0,AC13*V13,0) -> 0 | AE13: =IF(AC13>0,(M13-V13)*AC13,0) -> 0 | AF13: =IF(AA13<>"COMPRAR","",IF(AB13="",IF(X13="","",IF(X13-V13<0.01,"EMPATE TÉCNICO","")),IF(AB13<I13,"ESTOQUE INSUFICIENTE",IF(X13="","",IF(X13-V13<0.01,"EMPATE TÉCNICO",""))))) | AG13: BATEL COMERCIO DE ALIMENTOS LTDA | AH13: BABY/KIDS
A14: 657171 | B14: 7896699021982 | C14: 4814-01-AZ CH ZOO BONA SIL O T1 AZUL CX/6 - LOLLY | D14: LOLLY | E14: 1 | F14: C | G14: 3 | H14: 2.1 | I14: 3 | J14: 6.35 | K14: 6.35 | L14: 6.35 | M14: =IF(J14>0,J14,K14)*E14 -> 6.35 | O14: =IF(R14="","",ROUND(R14*(1-Premissas!$B$4),4)) -> 7.6 | R14: 8 | U14: 88 | V14: =IF(COUNT(N14:Q14)=0,"",MIN(N14:Q14)) -> 7.6 | W14: =IF(V14="","",INDEX($N$4:$Q$4,MATCH(V14,N14:Q14,0))) -> MEDCENTRO | X14: =IF(COUNT(N14:Q14)<2,"",SMALL(N14:Q14,2)) | Y14: =IF(OR(V14="",M14=0),"",V14/M14-1) -> 0.19685039 | Z14: =IF(OR(V14="",L14=""),"",V14/(L14*E14)-1) -> 0.19685039 | AA14: =IF(V14="","SEM OFERTA",IF(OR(Y14>Premissas!$B$11,Y14<Premissas!$B$12),"VERIFICAR - UNIDADE/EMBALAGEM",IF(Y14>Premissas!$B$6,"NÃO COMPRAR - REAJUSTE >5%","COMPRAR"))) -> NÃO COMPRAR - REAJUSTE >5% | AB14: =IF(W14="DIMEC",S14,IF(W14="MEDCENTRO",U14,"")) -> 88 | AC14: =IF(AA14<>"COMPRAR",0,IF(AB14="",I14,MIN(I14,AB14))) -> 0 | AD14: =IF(AC14>0,AC14*V14,0) -> 0 | AE14: =IF(AC14>0,(M14-V14)*AC14,0) -> 0 | AF14: =IF(AA14<>"COMPRAR","",IF(AB14="",IF(X14="","",IF(X14-V14<0.01,"EMPATE TÉCNICO","")),IF(AB14<I14,"ESTOQUE INSUFICIENTE",IF(X14="","",IF(X14-V14<0.01,"EMPATE TÉCNICO",""))))) | AG14: BATEL COMERCIO DE ALIMENTOS LTDA | AH14: BABY/KIDS
A15: 653461 | B15: 7896699033244 | C15: 4915-01-F CH VIVA SIL O T2 F LOLLY | D15: LOLLY | E15: 1 | F15: C | G15: 0 | H15: 0.1 | I15: 1 | J15: 8.76 | K15: 8.76 | L15: 8.76 | M15: =IF(J15>0,J15,K15)*E15 -> 8.76 | O15: =IF(R15="","",ROUND(R15*(1-Premissas!$B$4),4)) -> 8.8065 | R15: 9.27 | U15: 36 | V15: =IF(COUNT(N15:Q15)=0,"",MIN(N15:Q15)) -> 8.8065 | W15: =IF(V15="","",INDEX($N$4:$Q$4,MATCH(V15,N15:Q15,0))) -> MEDCENTRO | X15: =IF(COUNT(N15:Q15)<2,"",SMALL(N15:Q15,2)) | Y15: =IF(OR(V15="",M15=0),"",V15/M15-1) -> 0.0053082192 | Z15: =IF(OR(V15="",L15=""),"",V15/(L15*E15)-1) -> 0.0053082192 | AA15: =IF(V15="","SEM OFERTA",IF(OR(Y15>Premissas!$B$11,Y15<Premissas!$B$12),"VERIFICAR - UNIDADE/EMBALAGEM",IF(Y15>Premissas!$B$6,"NÃO COMPRAR - REAJUSTE >5%","COMPRAR"))) -> COMPRAR | AB15: =IF(W15="DIMEC",S15,IF(W15="MEDCENTRO",U15,"")) -> 36 | AC15: =IF(AA15<>"COMPRAR",0,IF(AB15="",I15,MIN(I15,AB15))) -> 1 | AD15: =IF(AC15>0,AC15*V15,0) -> 8.8065 | AE15: =IF(AC15>0,(M15-V15)*AC15,0) -> -0.0465 | AF15: =IF(AA15<>"COMPRAR","",IF(AB15="",IF(X15="","",IF(X15-V15<0.01,"EMPATE TÉCNICO","")),IF(AB15<I15,"ESTOQUE INSUFICIENTE",IF(X15="","",IF(X15-V15<0.01,"EMPATE TÉCNICO",""))))) | AG15: BATEL COMERCIO DE ALIMENTOS LTDA | AH15: BABY/KIDS
A16: 653581 | B16: 7896699025195 | C16: 5214-01-F CH OCEANO SIL O T1 ROSA CX/6 - LOLLY | D16: LOLLY | E16: 1 | F16: B | G16: 1 | H16: 1.6 | I16: 4 | J16: 8.46 | K16: 8.46 | L16: 8.46 | M16: =IF(J16>0,J16,K16)*E16 -> 8.46 | O16: =IF(R16="","",ROUND(R16*(1-Premissas!$B$4),4)) -> 10.051 | R16: 10.58 | U16: 152 | V16: =IF(COUNT(N16:Q16)=0,"",MIN(N16:Q16)) -> 10.051 | W16: =IF(V16="","",INDEX($N$4:$Q$4,MATCH(V16,N16:Q16,0))) -> MEDCENTRO | X16: =IF(COUNT(N16:Q16)<2,"",SMALL(N16:Q16,2)) | Y16: =IF(OR(V16="",M16=0),"",V16/M16-1) -> 0.18806147 | Z16: =IF(OR(V16="",L16=""),"",V16/(L16*E16)-1) -> 0.18806147 | AA16: =IF(V16="","SEM OFERTA",IF(OR(Y16>Premissas!$B$11,Y16<Premissas!$B$12),"VERIFICAR - UNIDADE/EMBALAGEM",IF(Y16>Premissas!$B$6,"NÃO COMPRAR - REAJUSTE >5%","COMPRAR"))) -> NÃO COMPRAR - REAJUSTE >5% | AB16: =IF(W16="DIMEC",S16,IF(W16="MEDCENTRO",U16,"")) -> 152 | AC16: =IF(AA16<>"COMPRAR",0,IF(AB16="",I16,MIN(I16,AB16))) -> 0 | AD16: =IF(AC16>0,AC16*V16,0) -> 0 | AE16: =IF(AC16>0,(M16-V16)*AC16,0) -> 0 | AF16: =IF(AA16<>"COMPRAR","",IF(AB16="",IF(X16="","",IF(X16-V16<0.01,"EMPATE TÉCNICO","")),IF(AB16<I16,"ESTOQUE INSUFICIENTE",IF(X16="","",IF(X16-V16<0.01,"EMPATE TÉCNICO",""))))) | AG16: BATEL COMERCIO DE ALIMENTOS LTDA | AH16: BABY/KIDS
A17: 643591 | B17: 7896699032230 | C17: 6014-01-F CH 100% SILICONE OT1 F LOLLY | D17: LOLLY | E17: 1 | F17: B | G17: 0 | H17: 0.7 | I17: 2 | J17: 15.13 | K17: 15.13 | L17: 15.13 | M17: =IF(J17>0,J17,K17)*E17 -> 15.13 | O17: =IF(R17="","",ROUND(R17*(1-Premissas!$B$4),4)) -> 15.2095 | R17: 16.01 | U17: 472 | V17: =IF(COUNT(N17:Q17)=0,"",MIN(N17:Q17)) -> 15.2095 | W17: =IF(V17="","",INDEX($N$4:$Q$4,MATCH(V17,N17:Q17,0))) -> MEDCENTRO | X17: =IF(COUNT(N17:Q17)<2,"",SMALL(N17:Q17,2)) | Y17: =IF(OR(V17="",M17=0),"",V17/M17-1) -> 0.0052544613 | Z17: =IF(OR(V17="",L17=""),"",V17/(L17*E17)-1) -> 0.0052544613 | AA17: =IF(V17="","SEM OFERTA",IF(OR(Y17>Premissas!$B$11,Y17<Premissas!$B$12),"VERIFICAR - UNIDADE/EMBALAGEM",IF(Y17>Premissas!$B$6,"NÃO COMPRAR - REAJUSTE >5%","COMPRAR"))) -> COMPRAR | AB17: =IF(W17="DIMEC",S17,IF(W17="MEDCENTRO",U17,"")) -> 472 | AC17: =IF(AA17<>"COMPRAR",0,IF(AB17="",I17,MIN(I17,AB17))) -> 2 | AD17: =IF(AC17>0,AC17*V17,0) -> 30.419 | AE17: =IF(AC17>0,(M17-V17)*AC17,0) -> -0.159 | AF17: =IF(AA17<>"COMPRAR","",IF(AB17="",IF(X17="","",IF(X17-V17<0.01,"EMPATE TÉCNICO","")),IF(AB17<I17,"ESTOQUE INSUFICIENTE",IF(X17="","",IF(X17-V17<0.01,"EMPATE TÉCNICO",""))))) | AG17: BATEL COMERCIO DE ALIMENTOS LTDA | AH17: BABY/KIDS
A18: 643631 | B18: 7896699019989 | C18: 7225-01 TIRA LEITE LOLLY | D18: LOLLY | E18: 1 | F18: C | G18: 2 | H18: 0.9 | I18: 1 | J18: 26.35 | K18: 26.35 | L18: 26.35 | M18: =IF(J18>0,J18,K18)*E18 -> 26.35 | O18: =IF(R18="","",ROUND(R18*(1-Premissas!$B$4),4)) -> 32.1195 | R18: 33.81 | U18: 96 | V18: =IF(COUNT(N18:Q18)=0,"",MIN(N18:Q18)) -> 32.1195 | W18: =IF(V18="","",INDEX($N$4:$Q$4,MATCH(V18,N18:Q18,0))) -> MEDCENTRO | X18: =IF(COUNT(N18:Q18)<2,"",SMALL(N18:Q18,2)) | Y18: =IF(OR(V18="",M18=0),"",V18/M18-1) -> 0.21895636 | Z18: =IF(OR(V18="",L18=""),"",V18/(L18*E18)-1) -> 0.21895636 | AA18: =IF(V18="","SEM OFERTA",IF(OR(Y18>Premissas!$B$11,Y18<Premissas!$B$12),"VERIFICAR - UNIDADE/EMBALAGEM",IF(Y18>Premissas!$B$6,"NÃO COMPRAR - REAJUSTE >5%","COMPRAR"))) -> NÃO COMPRAR - REAJUSTE >5% | AB18: =IF(W18="DIMEC",S18,IF(W18="MEDCENTRO",U18,"")) -> 96 | AC18: =IF(AA18<>"COMPRAR",0,IF(AB18="",I18,MIN(I18,AB18))) -> 0 | AD18: =IF(AC18>0,AC18*V18,0) -> 0 | AE18: =IF(AC18>0,(M18-V18)*AC18,0) -> 0 | AF18: =IF(AA18<>"COMPRAR","",IF(AB18="",IF(X18="","",IF(X18-V18<0.01,"EMPATE TÉCNICO","")),IF(AB18<I18,"ESTOQUE INSUFICIENTE",IF(X18="","",IF(X18-V18<0.01,"EMPATE TÉCNICO",""))))) | AG18: BATEL COMERCIO DE ALIMENTOS LTDA | AH18: BABY/KIDS
... A20: 610631 | B20: 7896699011617 | C20: BICO MAMAD SIL BIG REDONDO | D20: LOLLY | E20: 1 | F20: C | G20: 2 | H20: 0.9 | I20: 1 | J20: 7.51 | K20: 7.51 | L20: 7.51 | M20: =IF(J20>0,J20,K20)*E20 -> 7.51 | O20: =IF(R20="","",ROUND(R20*(1-Premissas!$B$4),4)) -> 7.828 | R20: 8.24 | U20: 391 | V20: =IF(COUNT(N20:Q20)=0,"",MIN(N20:Q20)) -> 7.828 | W20: =IF(V20="","",INDEX($N$4:$Q$4,MATCH(V20,N20:Q20,0))) -> MEDCENTRO | X20: =IF(COUNT(N20:Q20)<2,"",SMALL(N20:Q20,2)) | Y20: =IF(OR(V20="",M20=0),"",V20/M20-1) -> 0.042343542 | Z20: =IF(OR(V20="",L20=""),"",V20/(L20*E20)-1) -> 0.042343542 | AA20: =IF(V20="","SEM OFERTA",IF(OR(Y20>Premissas!$B$11,Y20<Premissas!$B$12),"VERIFICAR - UNIDADE/EMBALAGEM",IF(Y20>Premissas!$B$6,"NÃO COMPRAR - REAJUSTE >5%","COMPRAR"))) -> COMPRAR | AB20: =IF(W20="DIMEC",S20,IF(W20="MEDCENTRO",U20,"")) -> 391 | AC20: =IF(AA20<>"COMPRAR",0,IF(AB20="",I20,MIN(I20,AB20))) -> 1 | AD20: =IF(AC20>0,AC20*V20,0) -> 7.828 | AE20: =IF(AC20>0,(M20-V20)*AC20,0) -> -0.318 | AF20: =IF(AA20<>"COMPRAR","",IF(AB20="",IF(X20="","",IF(X20-V20<0.01,"EMPATE TÉCNICO","")),IF(AB20<I20,"ESTOQUE INSUFICIENTE",IF(X20="","",IF(X20-V20<0.01,"EMPATE TÉCNICO",""))))) | AG20: M C F RODRIGUES DE ANDRADE DIST IMPORT EXP ALIMENTO EIRELI | AH20: BABY/KIDS
A21: 619101 | B21: 7898953484243 | C21: BICO P/ SERINGA DE LAVAGEN NASAL C/2 | D21: 3B | E21: 1 | F21: B | G21: 11 | H21: 5 | I21: 2 | J21: 4.3 | K21: 4.3 | L21: 4.3 | M21: =IF(J21>0,J21,K21)*E21 -> 4.3 | N21: 4.3 | O21: =IF(R21="","",ROUND(R21*(1-Premissas!$B$4),4)) -> 4.37 | R21: 4.6 | S21: 988 | T21: 100 | U21: 252 | V21: =IF(COUNT(N21:Q21)=0,"",MIN(N21:Q21)) -> 4.3 | W21: =IF(V21="","",INDEX($N$4:$Q$4,MATCH(V21,N21:Q21,0))) -> DIMEC | X21: =IF(COUNT(N21:Q21)<2,"",SMALL(N21:Q21,2)) -> 4.37 | Y21: =IF(OR(V21="",M21=0),"",V21/M21-1) -> 0 | Z21: =IF(OR(V21="",L21=""),"",V21/(L21*E21)-1) -> 0 | AA21: =IF(V21="","SEM OFERTA",IF(OR(Y21>Premissas!$B$11,Y21<Premissas!$B$12),"VERIFICAR - UNIDADE/EMBALAGEM",IF(Y21>Premissas!$B$6,"NÃO COMPRAR - REAJUSTE >5%","COMPRAR"))) -> COMPRAR | AB21: =IF(W21="DIMEC",S21,IF(W21="MEDCENTRO",U21,"")) -> 988 | AC21: =IF(AA21<>"COMPRAR",0,IF(AB21="",I21,MIN(I21,AB21))) -> 2 | AD21: =IF(AC21>0,AC21*V21,0) -> 8.6 | AE21: =IF(AC21>0,(M21-V21)*AC21,0) -> 0 | AF21: =IF(AA21<>"COMPRAR","",IF(AB21="",IF(X21="","",IF(X21-V21<0.01,"EMPATE TÉCNICO","")),IF(AB21<I21,"ESTOQUE INSUFICIENTE",IF(X21="","",IF(X21-V21<0.01,"EMPATE TÉCNICO",""))))) | AG21: CENTROFARMA DISTRIBUIDORA FARMACEUTICA LTDA | AH21: BABY/KIDS
A22: 603521 | B22: 7896033233736 | C22: CANECA LILLO AP S 150ML MENINA | D22: LILLO | E22: 1 | F22: C | G22: 0 | H22: 0.1 | I22: 1 | J22: 25.77 | K22: 25.77 | L22: 25.77 | M22: =IF(J22>0,J22,K22)*E22 -> 25.77 | O22: =IF(R22="","",ROUND(R22*(1-Premissas!$B$4),4)) -> 25.346 | R22: 26.68 | U22: 18 | V22: =IF(COUNT(N22:Q22)=0,"",MIN(N22:Q22)) -> 25.346 | W22: =IF(V22="","",INDEX($N$4:$Q$4,MATCH(V22,N22:Q22,0))) -> MEDCENTRO | X22: =IF(COUNT(N22:Q22)<2,"",SMALL(N22:Q22,2)) | Y22: =IF(OR(V22="",M22=0),"",V22/M22-1) -> -0.01645324 | Z22: =IF(OR(V22="",L22=""),"",V22/(L22*E22)-1) -> -0.01645324 | AA22: =IF(V22="","SEM OFERTA",IF(OR(Y22>Premissas!$B$11,Y22<Premissas!$B$12),"VERIFICAR - UNIDADE/EMBALAGEM",IF(Y22>Premissas!$B$6,"NÃO COMPRAR - REAJUSTE >5%","COMPRAR"))) -> COMPRAR | AB22: =IF(W22="DIMEC",S22,IF(W22="MEDCENTRO",U22,"")) -> 18 | AC22: =IF(AA22<>"COMPRAR",0,IF(AB22="",I22,MIN(I22,AB22))) -> 1 | AD22: =IF(AC22>0,AC22*V22,0) -> 25.346 | AE22: =IF(AC22>0,(M22-V22)*AC22,0) -> 0.424 | AF22: =IF(AA22<>"COMPRAR","",IF(AB22="",IF(X22="","",IF(X22-V22<0.01,"EMPATE TÉCNICO","")),IF(AB22<I22,"ESTOQUE INSUFICIENTE",IF(X22="","",IF(X22-V22<0.01,"EMPATE TÉCNICO",""))))) | AG22: CENTROFARMA DISTRIBUIDORA FARMACEUTICA LTDA | AH22: BABY/KIDS
A23: 603531 | B23: 7896033233729 | C23: CANECA LILLO AP S 150ML MENINO | D23: LILLO | E23: 1 | F23: C | G23: 0 | H23: 0.2 | I23: 1 | J23: 25.77 | K23: 25.77 | L23: 25.77 | M23: =IF(J23>0,J23,K23)*E23 -> 25.77 | O23: =IF(R23="","",ROUND(R23*(1-Premissas!$B$4),4)) -> 24.035 | R23: 25.3 | U23: 3 | V23: =IF(COUNT(N23:Q23)=0,"",MIN(N23:Q23)) -> 24.035 | W23: =IF(V23="","",INDEX($N$4:$Q$4,MATCH(V23,N23:Q23,0))) -> MEDCENTRO | X23: =IF(COUNT(N23:Q23)<2,"",SMALL(N23:Q23,2)) | Y23: =IF(OR(V23="",M23=0),"",V23/M23-1) -> -0.067326348 | Z23: =IF(OR(V23="",L23=""),"",V23/(L23*E23)-1) -> -0.067326348 | AA23: =IF(V23="","SEM OFERTA",IF(OR(Y23>Premissas!$B$11,Y23<Premissas!$B$12),"VERIFICAR - UNIDADE/EMBALAGEM",IF(Y23>Premissas!$B$6,"NÃO COMPRAR - REAJUSTE >5%","COMPRAR"))) -> COMPRAR | AB23: =IF(W23="DIMEC",S23,IF(W23="MEDCENTRO",U23,"")) -> 3 | AC23: =IF(AA23<>"COMPRAR",0,IF(AB23="",I23,MIN(I23,AB23))) -> 1 | AD23: =IF(AC23>0,AC23*V23,0) -> 24.035 | AE23: =IF(AC23>0,(M23-V23)*AC23,0) -> 1.735 | AF23: =IF(AA23<>"COMPRAR","",IF(AB23="",IF(X23="","",IF(X23-V23<0.01,"EMPATE TÉCNICO","")),IF(AB23<I23,"ESTOQUE INSUFICIENTE",IF(X23="","",IF(X23-V23<0.01,"EMPATE TÉCNICO",""))))) | AG23: CENTROFARMA DISTRIBUIDORA FARMACEUTICA LTDA | AH23: BABY/KIDS
A24: 660051 | B24: 7896699011983 | C24: CHOCALHO INFANTIL N - LOLLY | D24: LOLLY | E24: 1 | F24: C | G24: 1 | H24: 0.7 | I24: 1 | J24: 13.79 | K24: 13.79 | L24: 13.79 | M24: =IF(J24>0,J24,K24)*E24 -> 13.79 | O24: =IF(R24="","",ROUND(R24*(1-Premissas!$B$4),4)) -> 15.048 | R24: 15.84 | U24: 122 | V24: =IF(COUNT(N24:Q24)=0,"",MIN(N24:Q24)) -> 15.048 | W24: =IF(V24="","",INDEX($N$4:$Q$4,MATCH(V24,N24:Q24,0))) -> MEDCENTRO | X24: =IF(COUNT(N24:Q24)<2,"",SMALL(N24:Q24,2)) | Y24: =IF(OR(V24="",M24=0),"",V24/M24-1) -> 0.091225526 | Z24: =IF(OR(V24="",L24=""),"",V24/(L24*E24)-1) -> 0.091225526 | AA24: =IF(V24="","SEM OFERTA",IF(OR(Y24>Premissas!$B$11,Y24<Premissas!$B$12),"VERIFICAR - UNIDADE/EMBALAGEM",IF(Y24>Premissas!$B$6,"NÃO COMPRAR - REAJUSTE >5%","COMPRAR"))) -> NÃO COMPRAR - REAJUSTE >5% | AB24: =IF(W24="DIMEC",S24,IF(W24="MEDCENTRO",U24,"")) -> 122 | AC24: =IF(AA24<>"COMPRAR",0,IF(AB24="",I24,MIN(I24,AB24))) -> 0 | AD24: =IF(AC24>0,AC24*V24,0) -> 0 | AE24: =IF(AC24>0,(M24-V24)*AC24,0) -> 0 | AF24: =IF(AA24<>"COMPRAR","",IF(AB24="",IF(X24="","",IF(X24-V24<0.01,"EMPATE TÉCNICO","")),IF(AB24<I24,"ESTOQUE INSUFICIENTE",IF(X24="","",IF(X24-V24<0.01,"EMPATE TÉCNICO",""))))) | AG24: BATEL COMERCIO DE ALIMENTOS LTDA | AH24: BABY/KIDS
A25: 629761 | B25: 7896699015936 | C25: CHOCALHO LOLLY AZUL | D25: LOLLY | E25: 1 | F25: C | G25: 0 | H25: 0.1 | I25: 1 | J25: 14.97 | K25: 14.97 | L25: 14.97 | M25: =IF(J25>0,J25,K25)*E25 -> 14.97 | O25: =IF(R25="","",ROUND(R25*(1-Premissas!$B$4),4)) -> 15.048 | R25: 15.84 | U25: 340 | V25: =IF(COUNT(N25:Q25)=0,"",MIN(N25:Q25)) -> 15.048 | W25: =IF(V25="","",INDEX($N$4:$Q$4,MATCH(V25,N25:Q25,0))) -> MEDCENTRO | X25: =IF(COUNT(N25:Q25)<2,"",SMALL(N25:Q25,2)) | Y25: =IF(OR(V25="",M25=0),"",V25/M25-1) -> 0.0052104208 | Z25: =IF(OR(V25="",L25=""),"",V25/(L25*E25)-1) -> 0.0052104208 | AA25: =IF(V25="","SEM OFERTA",IF(OR(Y25>Premissas!$B$11,Y25<Premissas!$B$12),"VERIFICAR - UNIDADE/EMBALAGEM",IF(Y25>Premissas!$B$6,"NÃO COMPRAR - REAJUSTE >5%","COMPRAR"))) -> COMPRAR | AB25: =IF(W25="DIMEC",S25,IF(W25="MEDCENTRO",U25,"")) -> 340 | AC25: =IF(AA25<>"COMPRAR",0,IF(AB25="",I25,MIN(I25,AB25))) -> 1 | AD25: =IF(AC25>0,AC25*V25,0) -> 15.048 | AE25: =IF(AC25>0,(M25-V25)*AC25,0) -> -0.078 | AF25: =IF(AA25<>"COMPRAR","",IF(AB25="",IF(X25="","",IF(X25-V25<0.01,"EMPATE TÉCNICO","")),IF(AB25<I25,"ESTOQUE INSUFICIENTE",IF(X25="","",IF(X25-V25<0.01,"EMPATE TÉCNICO",""))))) | AG25: M C F RODRIGUES DE ANDRADE DIST IMPORT EXP ALIMENTO EIRELI | AH25: BABY/KIDS
A26: 629771 | B26: 7896699015950 | C26: CHOCALHO LOLLY ROSA | D26: LOLLY | E26: 1 | F26: C | G26: 0 | H26: 0 | I26: 1 | J26: 14.49 | K26: 14.49 | L26: 14.49 | M26: =IF(J26>0,J26,K26)*E26 -> 14.49 | O26: =IF(R26="","",ROUND(R26*(1-Premissas!$B$4),4)) -> 15.048 | R26: 15.84 | U26: 258 | V26: =IF(COUNT(N26:Q26)=0,"",MIN(N26:Q26)) -> 15.048 | W26: =IF(V26="","",INDEX($N$4:$Q$4,MATCH(V26,N26:Q26,0))) -> MEDCENTRO | X26: =IF(COUNT(N26:Q26)<2,"",SMALL(N26:Q26,2)) | Y26: =IF(OR(V26="",M26=0),"",V26/M26-1) -> 0.038509317 | Z26: =IF(OR(V26="",L26=""),"",V26/(L26*E26)-1) -> 0.038509317 | AA26: =IF(V26="","SEM OFERTA",IF(OR(Y26>Premissas!$B$11,Y26<Premissas!$B$12),"VERIFICAR - UNIDADE/EMBALAGEM",IF(Y26>Premissas!$B$6,"NÃO COMPRAR - REAJUSTE >5%","COMPRAR"))) -> COMPRAR | AB26: =IF(W26="DIMEC",S26,IF(W26="MEDCENTRO",U26,"")) -> 258 | AC26: =IF(AA26<>"COMPRAR",0,IF(AB26="",I26,MIN(I26,AB26))) -> 1 | AD26: =IF(AC26>0,AC26*V26,0) -> 15.048 | AE26: =IF(AC26>0,(M26-V26)*AC26,0) -> -0.558 | AF26: =IF(AA26<>"COMPRAR","",IF(AB26="",IF(X26="","",IF(X26-V26<0.01,"EMPATE TÉCNICO","")),IF(AB26<I26,"ESTOQUE INSUFICIENTE",IF(X26="","",IF(X26-V26<0.01,"EMPATE TÉCNICO",""))))) | AG26: M C F RODRIGUES DE ANDRADE DIST IMPORT EXP ALIMENTO EIRELI | AH26: BABY/KIDS
A27: 663371 | B27: 7896699021746 | C27: CHUPETA BONA SIL R T1 M - LOLLY | D27: LOLLY | E27: 1 | F27: C | G27: 2 | H27: 1.1 | I27: 1 | J27: 6.1 | K27: 6.1 | L27: 6.1 | M27: =IF(J27>0,J27,K27)*E27 -> 6.1 | O27: =IF(R27="","",ROUND(R27*(1-Premissas!$B$4),4)) -> 7.6 | R27: 8 | U27: 140 | V27: =IF(COUNT(N27:Q27)=0,"",MIN(N27:Q27)) -> 7.6 | W27: =IF(V27="","",INDEX($N$4:$Q$4,MATCH(V27,N27:Q27,0))) -> MEDCENTRO | X27: =IF(COUNT(N27:Q27)<2,"",SMALL(N27:Q27,2)) | Y27: =IF(OR(V27="",M27=0),"",V27/M27-1) -> 0.24590164 | Z27: =IF(OR(V27="",L27=""),"",V27/(L27*E27)-1) -> 0.24590164 | AA27: =IF(V27="","SEM OFERTA",IF(OR(Y27>Premissas!$B$11,Y27<Premissas!$B$12),"VERIFICAR - UNIDADE/EMBALAGEM",IF(Y27>Premissas!$B$6,"NÃO COMPRAR - REAJUSTE >5%","COMPRAR"))) -> NÃO COMPRAR - REAJUSTE >5% | AB27: =IF(W27="DIMEC",S27,IF(W27="MEDCENTRO",U27,"")) -> 140 | AC27: =IF(AA27<>"COMPRAR",0,IF(AB27="",I27,MIN(I27,AB27))) -> 0 | AD27: =IF(AC27>0,AC27*V27,0) -> 0 | AE27: =IF(AC27>0,(M27-V27)*AC27,0) -> 0 | AF27: =IF(AA27<>"COMPRAR","",IF(AB27="",IF(X27="","",IF(X27-V27<0.01,"EMPATE TÉCNICO","")),IF(AB27<I27,"ESTOQUE INSUFICIENTE",IF(X27="","",IF(X27-V27<0.01,"EMPATE TÉCNICO",""))))) | AG27: BATEL COMERCIO DE ALIMENTOS LTDA | AH27: BABY/KIDS
A28: 663421 | B28: 7896699025829 | C28: CHUPETA DREAMS CAP SIL O T1 M LOLLY | D28: LOLLY | E28: 1 | F28: C | G28: 1 | H28: 0.5 | I28: 1 | J28: 10.8 | K28: 10.8 | L28: 10.8 | M28: =IF(J28>0,J28,K28)*E28 -> 10.8 | O28: =IF(R28="","",ROUND(R28*(1-Premissas!$B$4),4)) -> 11.096 | R28: 11.68 | U28: 77 | V28: =IF(COUNT(N28:Q28)=0,"",MIN(N28:Q28)) -> 11.096 | W28: =IF(V28="","",INDEX($N$4:$Q$4,MATCH(V28,N28:Q28,0))) -> MEDCENTRO | X28: =IF(COUNT(N28:Q28)<2,"",SMALL(N28:Q28,2)) | Y28: =IF(OR(V28="",M28=0),"",V28/M28-1) -> 0.027407407 | Z28: =IF(OR(V28="",L28=""),"",V28/(L28*E28)-1) -> 0.027407407 | AA28: =IF(V28="","SEM OFERTA",IF(OR(Y28>Premissas!$B$11,Y28<Premissas!$B$12),"VERIFICAR - UNIDADE/EMBALAGEM",IF(Y28>Premissas!$B$6,"NÃO COMPRAR - REAJUSTE >5%","COMPRAR"))) -> COMPRAR | AB28: =IF(W28="DIMEC",S28,IF(W28="MEDCENTRO",U28,"")) -> 77 | AC28: =IF(AA28<>"COMPRAR",0,IF(AB28="",I28,MIN(I28,AB28))) -> 1 | AD28: =IF(AC28>0,AC28*V28,0) -> 11.096 | AE28: =IF(AC28>0,(M28-V28)*AC28,0) -> -0.296 | AF28: =IF(AA28<>"COMPRAR","",IF(AB28="",IF(X28="","",IF(X28-V28<0.01,"EMPATE TÉCNICO","")),IF(AB28<I28,"ESTOQUE INSUFICIENTE",IF(X28="","",IF(X28-V28<0.01,"EMPATE TÉCNICO",""))))) | AG28: BATEL COMERCIO DE ALIMENTOS LTDA | AH28: BABY/KIDS
A29: 660011 | B29: 7896699019538 | C29: CHUPETA DREAMS SIL O T1 LOLLY | D29: LOLLY | E29: 1 | F29: C | G29: 1 | H29: 0.9 | I29: 2 | J29: 9.46 | K29: 9.46 | L29: 9.46 | M29: =IF(J29>0,J29,K29)*E29 -> 9.46 | O29: =IF(R29="","",ROUND(R29*(1-Premissas!$B$4),4)) -> 10.051 | R29: 10.58 | U29: 64 | V29: =IF(COUNT(N29:Q29)=0,"",MIN(N29:Q29)) -> 10.051 | W29: =IF(V29="","",INDEX($N$4:$Q$4,MATCH(V29,N29:Q29,0))) -> MEDCENTRO | X29: =IF(COUNT(N29:Q29)<2,"",SMALL(N29:Q29,2)) | Y29: =IF(OR(V29="",M29=0),"",V29/M29-1) -> 0.062473573 | Z29: =IF(OR(V29="",L29=""),"",V29/(L29*E29)-1) -> 0.062473573 | AA29: =IF(V29="","SEM OFERTA",IF(OR(Y29>Premissas!$B$11,Y29<Premissas!$B$12),"VERIFICAR - UNIDADE/EMBALAGEM",IF(Y29>Premissas!$B$6,"NÃO COMPRAR - REAJUSTE >5%","COMPRAR"))) -> NÃO COMPRAR - REAJUSTE >5% | AB29: =IF(W29="DIMEC",S29,IF(W29="MEDCENTRO",U29,"")) -> 64 | AC29: =IF(AA29<>"COMPRAR",0,IF(AB29="",I29,MIN(I29,AB29))) -> 0 | AD29: =IF(AC29>0,AC29*V29,0) -> 0 | AE29: =IF(AC29>0,(M29-V29)*AC29,0) -> 0 | AF29: =IF(AA29<>"COMPRAR","",IF(AB29="",IF(X29="","",IF(X29-V29<0.01,"EMPATE TÉCNICO","")),IF(AB29<I29,"ESTOQUE INSUFICIENTE",IF(X29="","",IF(X29-V29<0.01,"EMPATE TÉCNICO",""))))) | AG29: BATEL COMERCIO DE ALIMENTOS LTDA | AH29: BABY/KIDS
A30: 663381 | B30: 7896699022002 | C30: CHUPETA ZOO BONA SIL O T1 ROSA CX/6 - LOLLY | D30: LOLLY | E30: 1 | F30: C | G30: 0 | H30: 0.8 | I30: 3 | J30: 6.35 | K30: 6.35 | L30: 6.35 | M30: =IF(J30>0,J30,K30)*E30 -> 6.35 | O30: =IF(R30="","",ROUND(R30*(1-Premissas!$B$4),4)) -> 7.6 | R30: 8 | U30: 93 | V30: =IF(COUNT(N30:Q30)=0,"",MIN(N30:Q30)) -> 7.6 | W30: =IF(V30="","",INDEX($N$4:$Q$4,MATCH(V30,N30:Q30,0))) -> MEDCENTRO | X30: =IF(COUNT(N30:Q30)<2,"",SMALL(N30:Q30,2)) | Y30: =IF(OR(V30="",M30=0),"",V30/M30-1) -> 0.19685039 | Z30: =IF(OR(V30="",L30=""),"",V30/(L30*E30)-1) -> 0.19685039 | AA30: =IF(V30="","SEM OFERTA",IF(OR(Y30>Premissas!$B$11,Y30<Premissas!$B$12),"VERIFICAR - UNIDADE/EMBALAGEM",IF(Y30>Premissas!$B$6,"NÃO COMPRAR - REAJUSTE >5%","COMPRAR"))) -> NÃO COMPRAR - REAJUSTE >5% | AB30: =IF(W30="DIMEC",S30,IF(W30="MEDCENTRO",U30,"")) -> 93 | AC30: =IF(AA30<>"COMPRAR",0,IF(AB30="",I30,MIN(I30,AB30))) -> 0 | AD30: =IF(AC30>0,AC30*V30,0) -> 0 | AE30: =IF(AC30>0,(M30-V30)*AC30,0) -> 0 | AF30: =IF(AA30<>"COMPRAR","",IF(AB30="",IF(X30="","",IF(X30-V30<0.01,"EMPATE TÉCNICO","")),IF(AB30<I30,"ESTOQUE INSUFICIENTE",IF(X30="","",IF(X30-V30<0.01,"EMPATE TÉCNICO",""))))) | AG30: BATEL COMERCIO DE ALIMENTOS LTDA | AH30: BABY/KIDS
A31: 539381 | B31: 7896699017718 | C31: CHUQUINHA LOLLY COM DESENHO SIL AZ | D31: LOLLY | E31: 1 | F31: B | G31: 1 | H31: 3.2 | I31: 8 | J31: 12.47 | K31: 12.47 | L31: 12.47 | M31: =IF(J31>0,J31,K31)*E31 -> 12.47 | O31: =IF(R31="","",ROUND(R31*(1-Premissas!$B$4),4)) -> 10.7825 | R31: 11.35 | U31: 258 | V31: =IF(COUNT(N31:Q31)=0,"",MIN(N31:Q31)) -> 10.7825 | W31: =IF(V31="","",INDEX($N$4:$Q$4,MATCH(V31,N31:Q31,0))) -> MEDCENTRO | X31: =IF(COUNT(N31:Q31)<2,"",SMALL(N31:Q31,2)) | Y31: =IF(OR(V31="",M31=0),"",V31/M31-1) -> -0.13532478 | Z31: =IF(OR(V31="",L31=""),"",V31/(L31*E31)-1) -> -0.13532478 | AA31: =IF(V31="","SEM OFERTA",IF(OR(Y31>Premissas!$B$11,Y31<Premissas!$B$12),"VERIFICAR - UNIDADE/EMBALAGEM",IF(Y31>Premissas!$B$6,"NÃO COMPRAR - REAJUSTE >5%","COMPRAR"))) -> COMPRAR | AB31: =IF(W31="DIMEC",S31,IF(W31="MEDCENTRO",U31,"")) -> 258 | AC31: =IF(AA31<>"COMPRAR",0,IF(AB31="",I31,MIN(I31,AB31))) -> 8 | AD31: =IF(AC31>0,AC31*V31,0) -> 86.26 | AE31: =IF(AC31>0,(M31-V31)*AC31,0) -> 13.5 | AF31: =IF(AA31<>"COMPRAR","",IF(AB31="",IF(X31="","",IF(X31-V31<0.01,"EMPATE TÉCNICO","")),IF(AB31<I31,"ESTOQUE INSUFICIENTE",IF(X31="","",IF(X31-V31<0.01,"EMPATE TÉCNICO",""))))) | AH31: BABY/KIDS
A32: 663521 | B32: 7896699033619 | C32: COLETOR LEITE MATERNO SILICONE CX/6 - LOLLY | D32: LOLLY | E32: 1 | F32: B | G32: 1 | H32: 0.5 | I32: 1 | J32: 46.11 | K32: 46.11 | L32: 46.11 | M32: =IF(J32>0,J32,K32)*E32 -> 46.11 | O32: =IF(R32="","",ROUND(R32*(1-Premissas!$B$4),4)) -> 54.511 | R32: 57.38 | U32: 27 | V32: =IF(COUNT(N32:Q32)=0,"",MIN(N32:Q32)) -> 54.511 | W32: =IF(V32="","",INDEX($N$4:$Q$4,MATCH(V32,N32:Q32,0))) -> MEDCENTRO | X32: =IF(COUNT(N32:Q32)<2,"",SMALL(N32:Q32,2)) | Y32: =IF(OR(V32="",M32=0),"",V32/M32-1) -> 0.18219475 | Z32: =IF(OR(V32="",L32=""),"",V32/(L32*E32)-1) -> 0.18219475 | AA32: =IF(V32="","SEM OFERTA",IF(OR(Y32>Premissas!$B$11,Y32<Premissas!$B$12),"VERIFICAR - UNIDADE/EMBALAGEM",IF(Y32>Premissas!$B$6,"NÃO COMPRAR - REAJUSTE >5%","COMPRAR"))) -> NÃO COMPRAR - REAJUSTE >5% | AB32: =IF(W32="DIMEC",S32,IF(W32="MEDCENTRO",U32,"")) -> 27 | AC32: =IF(AA32<>"COMPRAR",0,IF(AB32="",I32,MIN(I32,AB32))) -> 0 | AD32: =IF(AC32>0,AC32*V32,0) -> 0 | AE32: =IF(AC32>0,(M32-V32)*AC32,0) -> 0 | AF32: =IF(AA32<>"COMPRAR","",IF(AB32="",IF(X32="","",IF(X32-V32<0.01,"EMPATE TÉCNICO","")),IF(AB32<I32,"ESTOQUE INSUFICIENTE",IF(X32="","",IF(X32-V32<0.01,"EMPATE TÉCNICO",""))))) | AG32: BATEL COMERCIO DE ALIMENTOS LTDA | AH32: BABY/KIDS
A33: 619181 | B33: 7896699020169 | C33: COPO EDUCATIVO TIP 150ML AZUL 7100-00-M | D33: LOLLY | E33: 1 | F33: C | G33: 1 | H33: 0.9 | I33: 2 | J33: 10.6 | K33: 10.6 | L33: 10.6 | M33: =IF(J33>0,J33,K33)*E33 -> 10.6 | O33: =IF(R33="","",ROUND(R33*(1-Premissas!$B$4),4)) -> 12.1505 | R33: 12.79 | U33: 75 | V33: =IF(COUNT(N33:Q33)=0,"",MIN(N33:Q33)) -> 12.1505 | W33: =IF(V33="","",INDEX($N$4:$Q$4,MATCH(V33,N33:Q33,0))) -> MEDCENTRO | X33: =IF(COUNT(N33:Q33)<2,"",SMALL(N33:Q33,2)) | Y33: =IF(OR(V33="",M33=0),"",V33/M33-1) -> 0.14627358 | Z33: =IF(OR(V33="",L33=""),"",V33/(L33*E33)-1) -> 0.14627358 | AA33: =IF(V33="","SEM OFERTA",IF(OR(Y33>Premissas!$B$11,Y33<Premissas!$B$12),"VERIFICAR - UNIDADE/EMBALAGEM",IF(Y33>Premissas!$B$6,"NÃO COMPRAR - REAJUSTE >5%","COMPRAR"))) -> NÃO COMPRAR - REAJUSTE >5% | AB33: =IF(W33="DIMEC",S33,IF(W33="MEDCENTRO",U33,"")) -> 75 | AC33: =IF(AA33<>"COMPRAR",0,IF(AB33="",I33,MIN(I33,AB33))) -> 0 | AD33: =IF(AC33>0,AC33*V33,0) -> 0 | AE33: =IF(AC33>0,(M33-V33)*AC33,0) -> 0 | AF33: =IF(AA33<>"COMPRAR","",IF(AB33="",IF(X33="","",IF(X33-V33<0.01,"EMPATE TÉCNICO","")),IF(AB33<I33,"ESTOQUE INSUFICIENTE",IF(X33="","",IF(X33-V33<0.01,"EMPATE TÉCNICO",""))))) | AG33: BATEL COMERCIO DE ALIMENTOS LTDA | AH33: BABY/KIDS
A34: 619191 | B34: 7896699020183 | C34: COPO EDUCATIVO TIP 150ML ROSA 7100-00-F | D34: LOLLY | E34: 1 | F34: B | G34: 2 | H34: 2.1 | I34: 4 | J34: 10.6 | K34: 10.6 | L34: 10.6 | M34: =IF(J34>0,J34,K34)*E34 -> 10.6 | O34: =IF(R34="","",ROUND(R34*(1-Premissas!$B$4),4)) -> 12.1505 | R34: 12.79 | U34: 52 | V34: =IF(COUNT(N34:Q34)=0,"",MIN(N34:Q34)) -> 12.1505 | W34: =IF(V34="","",INDEX($N$4:$Q$4,MATCH(V34,N34:Q34,0))) -> MEDCENTRO | X34: =IF(COUNT(N34:Q34)<2,"",SMALL(N34:Q34,2)) | Y34: =IF(OR(V34="",M34=0),"",V34/M34-1) -> 0.14627358 | Z34: =IF(OR(V34="",L34=""),"",V34/(L34*E34)-1) -> 0.14627358 | AA34: =IF(V34="","SEM OFERTA",IF(OR(Y34>Premissas!$B$11,Y34<Premissas!$B$12),"VERIFICAR - UNIDADE/EMBALAGEM",IF(Y34>Premissas!$B$6,"NÃO COMPRAR - REAJUSTE >5%","COMPRAR"))) -> NÃO COMPRAR - REAJUSTE >5% | AB34: =IF(W34="DIMEC",S34,IF(W34="MEDCENTRO",U34,"")) -> 52 | AC34: =IF(AA34<>"COMPRAR",0,IF(AB34="",I34,MIN(I34,AB34))) -> 0 | AD34: =IF(AC34>0,AC34*V34,0) -> 0 | AE34: =IF(AC34>0,(M34-V34)*AC34,0) -> 0 | AF34: =IF(AA34<>"COMPRAR","",IF(AB34="",IF(X34="","",IF(X34-V34<0.01,"EMPATE TÉCNICO","")),IF(AB34<I34,"ESTOQUE INSUFICIENTE",IF(X34="","",IF(X34-V34<0.01,"EMPATE TÉCNICO",""))))) | AG34: BATEL COMERCIO DE ALIMENTOS LTDA | AH34: BABY/KIDS
A35: 632461 | B35: 7896647078457 | C35: CORTADOR DE UNHAS METAL - AZUL/ 7845 | D35: EMDISA | E35: 1 | F35: C | G35: 0 | H35: 0 | I35: 1 | J35: 4.32 | K35: 4.32 | L35: 4.32 | M35: =IF(J35>0,J35,K35)*E35 -> 4.32 | O35: =IF(R35="","",ROUND(R35*(1-Premissas!$B$4),4)) -> 5.5765 | R35: 5.87 | U35: 14 | V35: =IF(COUNT(N35:Q35)=0,"",MIN(N35:Q35)) -> 5.5765 | W35: =IF(V35="","",INDEX($N$4:$Q$4,MATCH(V35,N35:Q35,0))) -> MEDCENTRO | X35: =IF(COUNT(N35:Q35)<2,"",SMALL(N35:Q35,2)) | Y35: =IF(OR(V35="",M35=0),"",V35/M35-1) -> 0.29085648 | Z35: =IF(OR(V35="",L35=""),"",V35/(L35*E35)-1) -> 0.29085648 | AA35: =IF(V35="","SEM OFERTA",IF(OR(Y35>Premissas!$B$11,Y35<Premissas!$B$12),"VERIFICAR - UNIDADE/EMBALAGEM",IF(Y35>Premissas!$B$6,"NÃO COMPRAR - REAJUSTE >5%","COMPRAR"))) -> NÃO COMPRAR - REAJUSTE >5% | AB35: =IF(W35="DIMEC",S35,IF(W35="MEDCENTRO",U35,"")) -> 14 | AC35: =IF(AA35<>"COMPRAR",0,IF(AB35="",I35,MIN(I35,AB35))) -> 0 | AD35: =IF(AC35>0,AC35*V35,0) -> 0 | AE35: =IF(AC35>0,(M35-V35)*AC35,0) -> 0 | AF35: =IF(AA35<>"COMPRAR","",IF(AB35="",IF(X35="","",IF(X35-V35<0.01,"EMPATE TÉCNICO","")),IF(AB35<I35,"ESTOQUE INSUFICIENTE",IF(X35="","",IF(X35-V35<0.01,"EMPATE TÉCNICO",""))))) | AG35: EMDISA DISTRIBUIDORA LTDA | AH35: BABY/KIDS
A36: 632451 | B36: 7896647078440 | C36: CORTADOR DE UNHAS METAL - ROSA/ 7844 | D36: EMDISA | E36: 1 | F36: C | G36: 0 | H36: 0 | I36: 1 | J36: 4.32 | K36: 4.32 | L36: 4.32 | M36: =IF(J36>0,J36,K36)*E36 -> 4.32 | O36: =IF(R36="","",ROUND(R36*(1-Premissas!$B$4),4)) -> 5.548 | R36: 5.84 | U36: 20 | V36: =IF(COUNT(N36:Q36)=0,"",MIN(N36:Q36)) -> 5.548 | W36: =IF(V36="","",INDEX($N$4:$Q$4,MATCH(V36,N36:Q36,0))) -> MEDCENTRO | X36: =IF(COUNT(N36:Q36)<2,"",SMALL(N36:Q36,2)) | Y36: =IF(OR(V36="",M36=0),"",V36/M36-1) -> 0.28425926 | Z36: =IF(OR(V36="",L36=""),"",V36/(L36*E36)-1) -> 0.28425926 | AA36: =IF(V36="","SEM OFERTA",IF(OR(Y36>Premissas!$B$11,Y36<Premissas!$B$12),"VERIFICAR - UNIDADE/EMBALAGEM",IF(Y36>Premissas!$B$6,"NÃO COMPRAR - REAJUSTE >5%","COMPRAR"))) -> NÃO COMPRAR - REAJUSTE >5% | AB36: =IF(W36="DIMEC",S36,IF(W36="MEDCENTRO",U36,"")) -> 20 | AC36: =IF(AA36<>"COMPRAR",0,IF(AB36="",I36,MIN(I36,AB36))) -> 0 | AD36: =IF(AC36>0,AC36*V36,0) -> 0 | AE36: =IF(AC36>0,(M36-V36)*AC36,0) -> 0 | AF36: =IF(AA36<>"COMPRAR","",IF(AB36="",IF(X36="","",IF(X36-V36<0.01,"EMPATE TÉCNICO","")),IF(AB36<I36,"ESTOQUE INSUFICIENTE",IF(X36="","",IF(X36-V36<0.01,"EMPATE TÉCNICO",""))))) | AG36: EMDISA DISTRIBUIDORA LTDA | AH36: BABY/KIDS
A37: 610711 | B37: 7896699024112 | C37: ESCOVA MASSAGEADORA NEUTRA | D37: LOLLY | E37: 1 | F37: B | G37: 2 | H37: 1.1 | I37: 1 | J37: 8.74 | K37: 8.74 | L37: 8.74 | M37: =IF(J37>0,J37,K37)*E37 -> 8.74 | O37: =IF(R37="","",ROUND(R37*(1-Premissas!$B$4),4)) -> 9.2815 | R37: 9.77 | U37: 249 | V37: =IF(COUNT(N37:Q37)=0,"",MIN(N37:Q37)) -> 9.2815 | W37: =IF(V37="","",INDEX($N$4:$Q$4,MATCH(V37,N37:Q37,0))) -> MEDCENTRO | X37: =IF(COUNT(N37:Q37)<2,"",SMALL(N37:Q37,2)) | Y37: =IF(OR(V37="",M37=0),"",V37/M37-1) -> 0.061956522 | Z37: =IF(OR(V37="",L37=""),"",V37/(L37*E37)-1) -> 0.061956522 | AA37: =IF(V37="","SEM OFERTA",IF(OR(Y37>Premissas!$B$11,Y37<Premissas!$B$12),"VERIFICAR - UNIDADE/EMBALAGEM",IF(Y37>Premissas!$B$6,"NÃO COMPRAR - REAJUSTE >5%","COMPRAR"))) -> NÃO COMPRAR - REAJUSTE >5% | AB37: =IF(W37="DIMEC",S37,IF(W37="MEDCENTRO",U37,"")) -> 249 | AC37: =IF(AA37<>"COMPRAR",0,IF(AB37="",I37,MIN(I37,AB37))) -> 0 | AD37: =IF(AC37>0,AC37*V37,0) -> 0 | AE37: =IF(AC37>0,(M37-V37)*AC37,0) -> 0 | AF37: =IF(AA37<>"COMPRAR","",IF(AB37="",IF(X37="","",IF(X37-V37<0.01,"EMPATE TÉCNICO","")),IF(AB37<I37,"ESTOQUE INSUFICIENTE",IF(X37="","",IF(X37-V37<0.01,"EMPATE TÉCNICO",""))))) | AG37: BATEL COMERCIO DE ALIMENTOS LTDA | AH37: BABY/KIDS
A38: 671181 | B38: 7898639692856 | C38: INALADOR /NEB PORTATIL RED VIBR NEBMESH2 | D38: GTECH | E38: 1 | F38: A | G38: 0 | H38: 0.1 | I38: 1 | J38: 162.8 | K38: 162.8 | L38: 162.8 | M38: =IF(J38>0,J38,K38)*E38 -> 162.8 | N38: 135.39 | O38: =IF(R38="","",ROUND(R38*(1-Premissas!$B$4),4)) -> 137.579 | R38: 144.82 | S38: 24 | T38: 20 | U38: 186 | V38: =IF(COUNT(N38:Q38)=0,"",MIN(N38:Q38)) -> 135.39 | W38: =IF(V38="","",INDEX($N$4:$Q$4,MATCH(V38,N38:Q38,0))) -> DIMEC | X38: =IF(COUNT(N38:Q38)<2,"",SMALL(N38:Q38,2)) -> 137.579 | Y38: =IF(OR(V38="",M38=0),"",V38/M38-1) -> -0.16836609 | Z38: =IF(OR(V38="",L38=""),"",V38/(L38*E38)-1) -> -0.16836609 | AA38: =IF(V38="","SEM OFERTA",IF(OR(Y38>Premissas!$B$11,Y38<Premissas!$B$12),"VERIFICAR - UNIDADE/EMBALAGEM",IF(Y38>Premissas!$B$6,"NÃO COMPRAR - REAJUSTE >5%","COMPRAR"))) -> COMPRAR | AB38: =IF(W38="DIMEC",S38,IF(W38="MEDCENTRO",U38,"")) -> 24 | AC38: =IF(AA38<>"COMPRAR",0,IF(AB38="",I38,MIN(I38,AB38))) -> 1 | AD38: =IF(AC38>0,AC38*V38,0) -> 135.39 | AE38: =IF(AC38>0,(M38-V38)*AC38,0) -> 27.41 | AF38: =IF(AA38<>"COMPRAR","",IF(AB38="",IF(X38="","",IF(X38-V38<0.01,"EMPATE TÉCNICO","")),IF(AB38<I38,"ESTOQUE INSUFICIENTE",IF(X38="","",IF(X38-V38<0.01,"EMPATE TÉCNICO",""))))) | AG38: CENTROFARMA DISTRIBUIDORA FARMACEUTICA LTDA | AH38: BABY/KIDS
A39: 610691 | B39: 7896699022804 | C39: KIT ALIMENTACAO TIP 4PCS ROSA 7131-01 | D39: BUBA | E39: 1 | F39: C | G39: 0 | H39: 0 | I39: 1 | J39: 28.2 | K39: 28.2 | L39: 28.2 | M39: =IF(J39>0,J39,K39)*E39 -> 28.2 | O39: =IF(R39="","",ROUND(R39*(1-Premissas!$B$4),4)) -> 34.96 | R39: 36.8 | U39: 15 | V39: =IF(COUNT(N39:Q39)=0,"",MIN(N39:Q39)) -> 34.96 | W39: =IF(V39="","",INDEX($N$4:$Q$4,MATCH(V39,N39:Q39,0))) -> MEDCENTRO | X39: =IF(COUNT(N39:Q39)<2,"",SMALL(N39:Q39,2)) | Y39: =IF(OR(V39="",M39=0),"",V39/M39-1) -> 0.23971631 | Z39: =IF(OR(V39="",L39=""),"",V39/(L39*E39)-1) -> 0.23971631 | AA39: =IF(V39="","SEM OFERTA",IF(OR(Y39>Premissas!$B$11,Y39<Premissas!$B$12),"VERIFICAR - UNIDADE/EMBALAGEM",IF(Y39>Premissas!$B$6,"NÃO COMPRAR - REAJUSTE >5%","COMPRAR"))) -> NÃO COMPRAR - REAJUSTE >5% | AB39: =IF(W39="DIMEC",S39,IF(W39="MEDCENTRO",U39,"")) -> 15 | AC39: =IF(AA39<>"COMPRAR",0,IF(AB39="",I39,MIN(I39,AB39))) -> 0 | AD39: =IF(AC39>0,AC39*V39,0) -> 0 | AE39: =IF(AC39>0,(M39-V39)*AC39,0) -> 0 | AF39: =IF(AA39<>"COMPRAR","",IF(AB39="",IF(X39="","",IF(X39-V39<0.01,"EMPATE TÉCNICO","")),IF(AB39<I39,"ESTOQUE INSUFICIENTE",IF(X39="","",IF(X39-V39<0.01,"EMPATE TÉCNICO",""))))) | AG39: CENTROFARMA DISTRIBUIDORA FARMACEUTICA LTDA | AH39: BABY/KIDS
A40: 552061 | B40: 7898633380575 | C40: LENÇO UMEDECIDO SUAVE MEU BEBÊ MINHA VIDA PACOTE 40 UNIDADES | D40: NUTRIEX | E40: 1 | F40: C | G40: 0 | H40: 6.4 | I40: 17 | J40: 3.38 | K40: 3.38 | L40: 2.96 | M40: =IF(J40>0,J40,K40)*E40 -> 3.38 | N40: 2.98 | O40: =IF(R40="","",ROUND(R40*(1-Premissas!$B$4),4)) | S40: 392 | T40: 24 | V40: =IF(COUNT(N40:Q40)=0,"",MIN(N40:Q40)) -> 2.98 | W40: =IF(V40="","",INDEX($N$4:$Q$4,MATCH(V40,N40:Q40,0))) -> DIMEC | X40: =IF(COUNT(N40:Q40)<2,"",SMALL(N40:Q40,2)) | Y40: =IF(OR(V40="",M40=0),"",V40/M40-1) -> -0.1183432 | Z40: =IF(OR(V40="",L40=""),"",V40/(L40*E40)-1) -> 0.0067567568 | AA40: =IF(V40="","SEM OFERTA",IF(OR(Y40>Premissas!$B$11,Y40<Premissas!$B$12),"VERIFICAR - UNIDADE/EMBALAGEM",IF(Y40>Premissas!$B$6,"NÃO COMPRAR - REAJUSTE >5%","COMPRAR"))) -> COMPRAR | AB40: =IF(W40="DIMEC",S40,IF(W40="MEDCENTRO",U40,"")) -> 392 | AC40: =IF(AA40<>"COMPRAR",0,IF(AB40="",I40,MIN(I40,AB40))) -> 17 | AD40: =IF(AC40>0,AC40*V40,0) -> 50.66 | AE40: =IF(AC40>0,(M40-V40)*AC40,0) -> 6.8 | AF40: =IF(AA40<>"COMPRAR","",IF(AB40="",IF(X40="","",IF(X40-V40<0.01,"EMPATE TÉCNICO","")),IF(AB40<I40,"ESTOQUE INSUFICIENTE",IF(X40="","",IF(X40-V40<0.01,"EMPATE TÉCNICO",""))))) | AG40: MARTINS COM SERV DISTR SA | AH40: BABY/KIDS
A41: 629751 | B41: 7896699029179 | C41: LOLLY BIC MAM SIL B 0 T2 FL M BL 0068-01 | D41: LOLLY | E41: 1 | F41: C | G41: 0 | H41: 0.5 | I41: 2 | J41: 6.21 | K41: 6.21 | L41: 6.21 | M41: =IF(J41>0,J41,K41)*E41 -> 6.21 | O41: =IF(R41="","",ROUND(R41*(1-Premissas!$B$4),4)) -> 10.051 | R41: 10.58 | U41: 587 | V41: =IF(COUNT(N41:Q41)=0,"",MIN(N41:Q41)) -> 10.051 | W41: =IF(V41="","",INDEX($N$4:$Q$4,MATCH(V41,N41:Q41,0))) -> MEDCENTRO | X41: =IF(COUNT(N41:Q41)<2,"",SMALL(N41:Q41,2)) | Y41: =IF(OR(V41="",M41=0),"",V41/M41-1) -> 0.61851852 | Z41: =IF(OR(V41="",L41=""),"",V41/(L41*E41)-1) -> 0.61851852 | AA41: =IF(V41="","SEM OFERTA",IF(OR(Y41>Premissas!$B$11,Y41<Premissas!$B$12),"VERIFICAR - UNIDADE/EMBALAGEM",IF(Y41>Premissas!$B$6,"NÃO COMPRAR - REAJUSTE >5%","COMPRAR"))) -> NÃO COMPRAR - REAJUSTE >5% | AB41: =IF(W41="DIMEC",S41,IF(W41="MEDCENTRO",U41,"")) -> 587 | AC41: =IF(AA41<>"COMPRAR",0,IF(AB41="",I41,MIN(I41,AB41))) -> 0 | AD41: =IF(AC41>0,AC41*V41,0) -> 0 | AE41: =IF(AC41>0,(M41-V41)*AC41,0) -> 0 | AF41: =IF(AA41<>"COMPRAR","",IF(AB41="",IF(X41="","",IF(X41-V41<0.01,"EMPATE TÉCNICO","")),IF(AB41<I41,"ESTOQUE INSUFICIENTE",IF(X41="","",IF(X41-V41<0.01,"EMPATE TÉCNICO",""))))) | AG41: BATEL COMERCIO DE ALIMENTOS LTDA | AH41: BABY/KIDS
A42: 630951 | B42: 896699031547 | C42: LOLLY CHUP 100% SIL RT 1 F 6111-01-F | D42: LOLLY | E42: 1 | F42: B | G42: 4 | H42: 3.2 | I42: 5 | J42: 15.29 | K42: 15.29 | L42: 15.29 | M42: =IF(J42>0,J42,K42)*E42 -> 15.29 | O42: =IF(R42="","",ROUND(R42*(1-Premissas!$B$4),4)) -> 14.2785 | R42: 15.03 | U42: 422 | V42: =IF(COUNT(N42:Q42)=0,"",MIN(N42:Q42)) -> 14.2785 | W42: =IF(V42="","",INDEX($N$4:$Q$4,MATCH(V42,N42:Q42,0))) -> MEDCENTRO | X42: =IF(COUNT(N42:Q42)<2,"",SMALL(N42:Q42,2)) | Y42: =IF(OR(V42="",M42=0),"",V42/M42-1) -> -0.066154349 | Z42: =IF(OR(V42="",L42=""),"",V42/(L42*E42)-1) -> -0.066154349 | AA42: =IF(V42="","SEM OFERTA",IF(OR(Y42>Premissas!$B$11,Y42<Premissas!$B$12),"VERIFICAR - UNIDADE/EMBALAGEM",IF(Y42>Premissas!$B$6,"NÃO COMPRAR - REAJUSTE >5%","COMPRAR"))) -> COMPRAR | AB42: =IF(W42="DIMEC",S42,IF(W42="MEDCENTRO",U42,"")) -> 422 | AC42: =IF(AA42<>"COMPRAR",0,IF(AB42="",I42,MIN(I42,AB42))) -> 5 | AD42: =IF(AC42>0,AC42*V42,0) -> 71.3925 | AE42: =IF(AC42>0,(M42-V42)*AC42,0) -> 5.0575 | AF42: =IF(AA42<>"COMPRAR","",IF(AB42="",IF(X42="","",IF(X42-V42<0.01,"EMPATE TÉCNICO","")),IF(AB42<I42,"ESTOQUE INSUFICIENTE",IF(X42="","",IF(X42-V42<0.01,"EMPATE TÉCNICO",""))))) | AG42: BATEL COMERCIO DE ALIMENTOS LTDA | AH42: BABY/KIDS
...

Sheet Premissas
A1: Premissas e parâmetros da cotação
A3: Parâmetro | B3: Valor | C3: Observação / fonte
A4: Desconto adicional MEDCENTRO (sobre PRECO_FINAL) | B4: 0.05 | C4: Informado pelo usuário em 20/10/2026
A5: Preço DIMEC | B5: PRECO 2% = preço final | C5: Informado pelo usuário: já é preço final, sem ajuste
A6: Limite de reajuste aceito (vs. preço de referência) | B6: 0.05 | C6: Regra do usuário: sem compra em reajuste superior a 5%
A7: Preço de referência | B7: Últ. preço compra (se 0/vazio, usa Custo un da lista) | C7: Fonte: Lista_de_Compra_20261020_150341.xlsx
A8: Quantidade e preço SEMPRE POR CAIXA | B8: Qtd = Caixas da Lista; ref. caixa = preço unitário × Un/Cx; distribuidor não vende fração | C8: Instrução do usuário. Qtd limitada ao estoque do vencedor (em caixas). Palmed não informa estoque; Q.MÁX do encarte será aplicada
A9: Palmed CAST x MAB | B9: Mesmo distribuidor, 2 setores logísticos, preços distintos — colunas separadas | C9: Aguardando planilha de correlação COD Palmed x EAN
A10: Casamento de itens | B10: Somente por EAN (principal + 5 adicionais). Sem casamento por descrição. | C10: Instrução do usuário
A11: Suspeita de unidade/embalagem divergente (var. acima de) | B11: 1 | C11: Premissa da análise: preço ofertado > 2x a referência indica unidade diferente (caixa x unidade/flaconete) ou ref. bonificada (R$0,01) — conferir antes de decidir
A12: Suspeita de unidade divergente (var. abaixo de) | B12: -0.5 | C12: Premissa da análise: oferta < metade da referência por caixa — provável Un/Cx incorreto na lista
A15: Legenda: células amarelas com texto azul são parâmetros editáveis — alterar recalcula toda a cotação.

Sheet Pedido DIMEC
A1: PEDIDO DIMEC — 20/10/2026 (preço final)
A3: Cód. interno | B3: EAN | C3: Produto | D3: Fabricante | E3: ABC | F3: Dem./mês | G3: Preço ref. (cx) | H3: Melhor 3m (un) | I3: Preço ofertado (cx) | J3: Var. vs ref. | K3: Qtd pedido (cx) | L3: Valor pedido | M3: Economia | N3: Estoque forn. | O3: Alerta
A4: =Cotação!A647 -> 634551 | B4: =Cotação!B647 -> 7895143226942 | C4: =Cotação!C647 -> 5MAG 500MG 60CAPS QUALYNUTRI | D4: =Cotação!D647 -> QUALYNUTRI | E4: =Cotação!F647 -> A | F4: =Cotação!H647 -> 3.2 | G4: =Cotação!M647 -> 33.53 | H4: =Cotação!L647 -> 33.53 | I4: =Cotação!V647 -> 33.53 | J4: =Cotação!Y647 -> 0 | K4: =Cotação!AC647 -> 6 | L4: =Cotação!AD647 -> 201.18 | M4: =Cotação!AE647 -> 0 | N4: =Cotação!AB647 -> 191 | O4: =Cotação!AF647
A5: =Cotação!A136 -> 2081 | B5: =Cotação!B136 -> 7899620912731 | C5: =Cotação!C136 -> ACEBROFILINA 10MG/ML XPE FR 120ML+COP MED | D5: =Cotação!D136 -> GLOBO | E5: =Cotação!F136 -> C | F5: =Cotação!H136 -> 1.2 | G5: =Cotação!M136 -> 7.01 | H5: =Cotação!L136 -> 7.01 | I5: =Cotação!V136 -> 7.13 | J5: =Cotação!Y136 -> 0.017118402 | K5: =Cotação!AC136 -> 2 | L5: =Cotação!AD136 -> 14.26 | M5: =Cotação!AE136 -> -0.24 | N5: =Cotação!AB136 -> 878 | O5: =Cotação!AF136
A6: =Cotação!A139 -> 6261 | B6: =Cotação!B139 -> 7896006267072 | C6: =Cotação!C139 -> ACETATO DE HIDROCORTISONA 10MG CREME DERM BG 20G | D6: =Cotação!D139 -> UNIAO QUIMICA | E6: =Cotação!F139 -> B | F6: =Cotação!H139 -> 2.9 | G6: =Cotação!M139 -> 7.473 | H6: =Cotação!L139 -> 7.47 | I6: =Cotação!V139 -> 7.08 | J6: =Cotação!Y139 -> -0.052589322 | K6: =Cotação!AC139 -> 1 | L6: =Cotação!AD139 -> 7.08 | M6: =Cotação!AE139 -> 0.393 | N6: =Cotação!AB139 -> 1183 | O6: =Cotação!AF139
A7: =Cotação!A143 -> 469021 | B7: =Cotação!B143 -> 7896004712031 | C7: =Cotação!C143 -> ACETONIDO TRIANCINOLONA 1MG POM BG 10G | D7: =Cotação!D143 -> GERMED GENERICOS | E7: =Cotação!F143 -> B | F7: =Cotação!H143 -> 4.9 | G7: =Cotação!M143 -> 4.02 | H7: =Cotação!L143 -> 4.02 | I7: =Cotação!V143 -> 4.08 | J7: =Cotação!Y143 -> 0.014925373 | K7: =Cotação!AC143 -> 12 | L7: =Cotação!AD143 -> 48.96 | M7: =Cotação!AE143 -> -0.72 | N7: =Cotação!AB143 -> 1178 | O7: =Cotação!AF143
A8: =Cotação!A148 -> 11821 | B8: =Cotação!B148 -> 7896112128847 | C8: =Cotação!C148 -> ACICLOVIR 50MG/G CREME DERM BG 10G | D8: =Cotação!D148 -> TEUTO | E8: =Cotação!F148 -> A | F8: =Cotação!H148 -> 20.4 | G8: =Cotação!M148 -> 4.9 | H8: =Cotação!L148 -> 4.9 | I8: =Cotação!V148 -> 5.09 | J8: =Cotação!Y148 -> 0.03877551 | K8: =Cotação!AC148 -> 19 | L8: =Cotação!AD148 -> 96.71 | M8: =Cotação!AE148 -> -3.61 | N8: =Cotação!AB148 -> 9678 | O8: =Cotação!AF148
A9: =Cotação!A1047 -> 2953 | B9: =Cotação!B1047 -> 7898665751411 | C9: =Cotação!C1047 -> ACIDO HIALURONICO+VITAMINAS 75MG C/60 CP | D9: =Cotação!D1047 -> DUOM | E9: =Cotação!F1047 -> C | F9: =Cotação!H1047 -> 0.1 | G9: =Cotação!M1047 -> 37.67 | H9: =Cotação!L1047 -> 37.67 | I9: =Cotação!V1047 -> 39.01 | J9: =Cotação!Y1047 -> 0.035572073 | K9: =Cotação!AC1047 -> 1 | L9: =Cotação!AD1047 -> 39.01 | M9: =Cotação!AE1047 -> -1.34 | N9: =Cotação!AB1047 -> 13 | O9: =Cotação!AF1047
A10: =Cotação!A657 -> 541181 | B10: =Cotação!B657 -> 7898048691419 | C10: =Cotação!C657 -> AGUA FLOR DE LARANJEIRA 100ML | D10: =Cotação!D657 -> LAPON | E10: =Cotação!F657 -> C | F10: =Cotação!H657 -> 0.8 | G10: =Cotação!M657 -> 5.06 | H10: =Cotação!L657 -> 5.06 | I10: =Cotação!V657 -> 5.25 | J10: =Cotação!Y657 -> 0.037549407 | K10: =Cotação!AC657 -> 2 | L10: =Cotação!AD657 -> 10.5 | M10: =Cotação!AE657 -> -0.38 | N10: =Cotação!AB657 -> 2168 | O10: =Cotação!AF657
A11: =Cotação!A993 -> 631571 | B11: =Cotação!B993 -> 7898652371967 | C11: =Cotação!C993 -> AGULHA HIPODERMICA 30X0,70MM | D11: =Cotação!D993 -> 0 | E11: =Cotação!F993 -> C | F11: =Cotação!H993 -> 31.2 | G11: =Cotação!M993 -> 14 | H11: =Cotação!L993 -> 0.14 | I11: =Cotação!V993 -> 12.44 | J11: =Cotação!Y993 -> -0.11142857 | K11: =Cotação!AC993 -> 1 | L11: =Cotação!AD993 -> 12.44 | M11: =Cotação!AE993 -> 1.56 | N11: =Cotação!AB993 -> 971 | O11: =Cotação!AF993
A12: =Cotação!A69 -> 3233 | B12: =Cotação!B69 -> 7896902210479 | C12: =Cotação!C69 -> ALCOOL 70% 50ML | D12: =Cotação!D69 -> FARMAX | E12: =Cotação!F69 -> A | F12: =Cotação!H69 -> 35.9 | G12: =Cotação!M69 -> 2.42 | H12: =Cotação!L69 -> 2.38 | I12: =Cotação!V69 -> 2.37 | J12: =Cotação!Y69 -> -0.020661157 | K12: =Cotação!AC69 -> 57 | L12: =Cotação!AD69 -> 135.09 | M12: =Cotação!AE69 -> 2.85 | N12: =Cotação!AB69 -> 3735 | O12: =Cotação!AF69
A13: =Cotação!A71 -> 5043 | B13: =Cotação!B71 -> 7898031310877 | C13: =Cotação!C71 -> ALCOOL GEL 70% 50G UNISSEPT | D13: =Cotação!D71 -> UNIPHAR | E13: =Cotação!F71 -> B | F13: =Cotação!H71 -> 5.4 | G13: =Cotação!M71 -> 3.51 | H13: =Cotação!L71 -> 3.51 | I13: =Cotação!V71 -> 3.51 | J13: =Cotação!Y71 -> 0 | K13: =Cotação!AC71 -> 8 | L13: =Cotação!AD71 -> 28.08 | M13: =Cotação!AE71 -> 0 | N13: =Cotação!AB71 -> 219 | O13: =Cotação!AF71
A14: =Cotação!A660 -> 571901 | B14: =Cotação!B660 -> 7898582291694 | C14: =Cotação!C660 -> ALCOOL GEL 70% PERFUMAD COM MICROES 60ML | D14: =Cotação!D660 -> PAIXAO | E14: =Cotação!F660 -> B | F14: =Cotação!H660 -> 3.2 | G14: =Cotação!M660 -> 5.6 | H14: =Cotação!L660 -> 5.59 | I14: =Cotação!V660 -> 5.6 | J14: =Cotação!Y660 -> 0 | K14: =Cotação!AC660 -> 8 | L14: =Cotação!AD660 -> 44.8 | M14: =Cotação!AE660 -> 0 | N14: =Cotação!AB660 -> 199 | O14: =Cotação!AF660
A15: =Cotação!A985 -> 3453 | B15: =Cotação!B985 -> 7898206190044 | C15: =Cotação!C985 -> ALCOOL J FERES 70% 1 LITRO | D15: =Cotação!D985 -> 0 | E15: =Cotação!F985 -> C | F15: =Cotação!H985 -> 0.1 | G15: =Cotação!M985 -> 9.21 | H15: =Cotação!L985 -> 9.21 | I15: =Cotação!V985 -> 8.98 | J15: =Cotação!Y985 -> -0.024972856 | K15: =Cotação!AC985 -> 1 | L15: =Cotação!AD985 -> 8.98 | M15: =Cotação!AE985 -> 0.23 | N15: =Cotação!AB985 -> 4660 | O15: =Cotação!AF985
A16: =Cotação!A662 -> 331061 | B16: =Cotação!B662 -> 7896523209715 | C16: =Cotação!C662 -> ALERGOMINE 10MG/G CREME BG 30G | D16: =Cotação!D662 -> CIMED | E16: =Cotação!F662 -> C | F16: =Cotação!H662 -> 1.5 | G16: =Cotação!M662 -> 6.89 | H16: =Cotação!L662 -> 6.89 | I16: =Cotação!V662 -> 4.99 | J16: =Cotação!Y662 -> -0.27576197 | K16: =Cotação!AC662 -> 4 | L16: =Cotação!AD662 -> 19.96 | M16: =Cotação!AE662 -> 7.6 | N16: =Cotação!AB662 -> 7 | O16: =Cotação!AF662
