Workbook

Sheet Resumo
A1: COTAÇÃO 04/09/2026 — DROGARIA ROCHA — RESUMO
A3: Distribuidor | B3: Itens | C3: Valor total (R$)
A4: ePan | B4: =COUNTIF(Comparativo!M:M,"EPAN") | C4: 7512.27
A5: SB LOG | B5: =COUNTIF(Comparativo!M:M,"SB LOG") | C5: 2865.3
A6: Tapajós | B6: =COUNTIF(Comparativo!M:M,"TAPAJOS") | C6: 11563.09
A7: Nazária | B7: =COUNTIF(Comparativo!M:M,"NAZARIA") | C7: 12388.861
A8: Sem cotação | B8: =COUNTIF(Comparativo!M:M,"SEM COTAÇÃO")
A10: Pedidos OL (arquivos separados, sem cotação)
A11: ACHE | B11: 36
A12: BIOLAB RX | B12: 9
A13: HALEON - RX | B13: 22
A14: HEBRON RX | B14: 11
A15: HYPERA - ALL | B15: 54
A16: KLEY HERTZ | B16: 2
A17: MYRALIS | B17: 3
A18: NEO QUIMICA - GENERICO | B18: 2
A19: OPELLA | B19: 7
A20: RECKIT GERAL - ELIANE | B20: 1
A21: UNIAO QUIMICA (GENOM) RX | B21: 17
A23: Obs: valores 'Valor total' calculados sobre preço cotado × qtd na base de faturamento de cada distribuidor.

Sheet Comparativo
A1: Cód. interno | B1: EAN princ. | C1: Produto | D1: Un/Cx | E1: Caixas | F1: Un. compradas | G1: Últ. compra (un) | H1: Menor hist. (un) | I1: ePan (un) | J1: SB LOG (un) | K1: Tapajós (un) | L1: Nazária (un) | M1: Vencedor | N1: Preço venc. (un) | O1: Dif. vs últ. compra | P1: Status | Q1: Obs
A2: 674181 | B2: 7891317049225 | C2: 10BI IMUNE C/30CP-DEMAIS PROD | D2: 1 | E2: 1 | F2: 1 | G2: 125.7 | H2: 118.3 | J2: 156.4 | K2: 119.3 | L2: 141.168 | M2: TAPAJOS | N2: 119.3 | O2: =N2/G2-1 | P2: OK (≤ últ. compra)
A3: 274461 | B3: 7898040320973 | C3: ABRILAR 7MG XPE FR 100ML+CM | D3: 1 | E3: 3 | F3: 3 | G3: 42.64 | H3: 33.1775 | I3: 43.09 | J3: 41.9 | L3: 41.0305 | M3: NAZARIA | N3: 41.0305 | O3: =N3/G3-1 | P3: OK (≤ últ. compra)
A4: 25403 | B4: 7897211100482 | C4: ABS P/SEIOS AMAME DIA&NOITE C/24-DEMAIS PROD | D4: 1 | E4: 2 | F4: 2 | G4: 21.76 | H4: 17.955 | I4: 16.92 | M4: EPAN | N4: 16.92 | O4: =N4/G4-1 | P4: OK (≤ menor hist.)
A5: 621421 | B5: 3282770206050 | C5: ACTINE PROT SOLAR FPS60 COR 40G | D5: 1 | E5: 1 | F5: 1 | G5: 54.91 | H5: 54.91 | L5: 67.03 | M5: NAZARIA | N5: 67.03 | O5: =N5/G5-1 | P5: ACIMA +22.1% (vs últ. compra)
A6: 642771 | B6: 7892828001016 | C6: ADEFORTE ORAL 01 AMP | D6: 1 | E6: 2 | F6: 2 | G6: 24.86 | H6: 17.3474 | I6: 21.42 | J6: 22.7 | L6: 28 | M6: EPAN | N6: 21.42 | O6: =N6/G6-1 | P6: OK (≤ últ. compra)
A7: 884 | B7: 7892828002303 | C7: ADEFORTE TURBO USO ORAL 2AMP 3ML | D7: 1 | E7: 8 | F7: 8 | G7: 44.79 | H7: 30.3708 | L7: 44.79 | M7: NAZARIA | N7: 44.79 | O7: =N7/G7-1 | P7: OK (≤ últ. compra)
A8: 647221 | B8: 7896023705397 | C8: AGUA INGLESA 500ML | D8: 1 | E8: 4 | F8: 4 | G8: 22.12 | H8: 22.12 | L8: 25.83 | M8: NAZARIA | N8: 25.83 | O8: =N8/G8-1 | P8: ACIMA +16.8% (vs últ. compra)
A9: 367361 | B9: 7891721023965 | C9: ALGINAC 1,0+100,0+100,0MG CX 10 COMP REV LIB RETARD | D9: 1 | E9: 4 | F9: 4 | G9: 51.946667 | H9: 43.42 | J9: 51.1 | L9: 51.0968 | M9: NAZARIA | N9: 51.0968 | O9: =N9/G9-1 | P9: OK (≤ últ. compra)
A10: 367421 | B10: 7891721029646 | C10: ALGINAC 1,0+50,0+50,0MG CX 30 CP | D10: 1 | E10: 1 | F10: 1 | G10: 50.34 | H10: 45.91 | J10: 52.1 | L10: 52.0812 | M10: NAZARIA | N10: 52.0812 | O10: =N10/G10-1 | P10: ACIMA +3.5% (vs últ. compra)
A11: 71981 | B11: 7896676414639 | C11: ANA-FLEX 35+300+50MG CX 200 COMP | D11: 20 | E11: 1 | F11: 20 | G11: 4.9505 | H11: 4.9505 | M11: SEM COTAÇÃO
A12: 469661 | B12: 7891317013967 | C12: ANDOLBA 4,5%+0,5%+0,5% AER TOP TB 43G | D12: 1 | E12: 2 | F12: 2 | G12: 28.045 | H12: 28.04 | K12: 30.01 | M12: TAPAJOS | N12: 30.01 | O12: =N12/G12-1 | P12: ACIMA +7.0% (vs últ. compra)
A13: 364361 | B13: 7898040321420 | C13: ANNITA 20MG/ML PO SUS ORAL FR 45ML | D13: 1 | E13: 2 | F13: 2 | G13: 25.125 | H13: 21.8625 | I13: 25.13 | J13: 24.9 | K13: 24.6 | L13: 24.434 | M13: NAZARIA | N13: 24.434 | O13: =N13/G13-1 | P13: OK (≤ últ. compra)
A14: 131861 | B14: 7896094200227 | C14: ANSITEC 5MG CX 20 COMP | D14: 1 | E14: 1 | F14: 1 | G14: 27.07 | H14: 27.07 | M14: SEM COTAÇÃO
A15: 624171 | B15: 7899706195089 | C15: ANTHELIOS LRP AIRLIC FL FPS50 S/COR 40ML | D15: 1 | E15: 1 | F15: 1 | G15: 88.16 | H15: 88.16 | M15: SEM COTAÇÃO
A16: 618051 | B16: 7908615030098 | C16: ANTHELIOS LRP AIRLIC FPS70 2.0 40G+NECESSARIE | D16: 1 | E16: 1 | F16: 1 | G16: 75.475 | H16: 75.475 | M16: SEM COTAÇÃO
A17: 648861 | B17: 7908615038384 | C17: ANTHELIOS LRP AIRLIC+FLUIDO FPS50+EFFACL CONC 50G | D17: 1 | E17: 1 | F17: 1 | G17: 112.82 | H17: 112.82 | L17: 110.51 | M17: SEM COTAÇÃO | Q17: sem estoque na Nazária
A18: 666011 | B18: 7898639690586 | C18: APAR PRES DIG HOME GP200 G-TECH-DEMAIS PROD | D18: 1 | E18: 2 | F18: 2 | G18: 73.038333 | H18: 73.0383 | M18: SEM COTAÇÃO
A19: 149921 | B19: 7896261018181 | C19: APRESOLINA 25MG CX 20 DRG | D19: 1 | E19: 1 | F19: 1 | G19: 7.963125 | H19: 6.64 | K19: 7.43 | M19: TAPAJOS | N19: 7.43 | O19: =N19/G19-1 | P19: OK (≤ últ. compra)
A20: 619611 | B20: 7898636190720 | C20: ASEPXIA PO COMPA MARFIM 10G | D20: 1 | E20: 1 | F20: 1 | G20: 36.43 | H20: 36.43 | M20: SEM COTAÇÃO
A21: 13901 | B21: 7793640000143 | C21: ASPIRINA 500MG BL X 20 COMP | D21: 1 | E21: 4 | F21: 4 | G21: 13.25 | H21: 12.36 | J21: 13.5 | L21: 13.95 | M21: SB LOG | N21: 13.5 | O21: =N21/G21-1 | P21: ACIMA +1.9% (vs últ. compra)
A22: 13921 | B22: 7891106915175 | C22: ASPIRINA 500MG CX 100 COMP ACLAR | D22: 10 | E22: 1 | F22: 10 | G22: 8.422 | H22: 7.2447 | M22: SEM COTAÇÃO
A23: 13301 | B23: 7891106001946 | C23: ASPIRINA PREVENT 100MG CX 30 COMP REV | D23: 1 | E23: 1 | F23: 1 | G23: 17.626 | H23: 16.8067 | I23: 17.62 | L23: 18.68 | M23: EPAN | N23: 17.62 | O23: =N23/G23-1 | P23: OK (≤ últ. compra)
A24: 47321 | B24: 7891317412692 | C24: ASTRO 600MG CX 1FA+DIL | D24: 1 | E24: 2 | F24: 2 | G24: 38.26 | H24: 38.26 | J24: 43.3 | K24: 41.97 | L24: 42.8736 | M24: TAPAJOS | N24: 41.97 | O24: =N24/G24-1 | P24: ACIMA +9.7% (vs últ. compra)
A25: 594191 | B25: 7891317014162 | C25: ATAK CLAV 875+125MG CX 14 COMP REV | D25: 1 | E25: 1 | F25: 1 | G25: 66.99 | H25: 49.5083 | J25: 56.1 | K25: 54.33 | L25: 55.488 | M25: TAPAJOS | N25: 54.33 | O25: =N25/G25-1 | P25: OK (≤ últ. compra)
A26: 637931 | B26: 7898968453098 | C26: ATENSINA 0,100MG CX 30 COMP | D26: 1 | E26: 1 | F26: 1 | G26: 7.045 | H26: 7.045 | I26: 7.91 | L26: 8.01 | M26: NAZARIA | N26: 8.01 | O26: =N26/G26-1 | P26: ACIMA +13.7% (vs últ. compra) | Q26: sem estoque no ePan
A27: 582181 | B27: 7896026307826 | C27: ATROVENT 0,25MG/ML SOL INAL CT FR VD AMB X 20ML | D27: 1 | E27: 3 | F27: 3 | G27: 22.33 | H27: 19.266 | J27: 23 | K27: 22.33 | L27: 23.75 | M27: TAPAJOS | N27: 22.33 | O27: =N27/G27-1 | P27: OK (≤ últ. compra)
A28: 488841 | B28: 7891317010287 | C28: ATTENZE 10MG CX 30 COMP | D28: 1 | E28: 1 | F28: 1 | G28: 32.778333 | H28: 32.7783 | J28: 39.8 | L28: 39.3792 | M28: NAZARIA | N28: 39.3792 | O28: =N28/G28-1 | P28: ACIMA +20.1% (vs últ. compra)
A29: 15761 | B29: 5702191025637 | C29: AZELAN 150 MG/G GEL CT BG AL X 30 G | D29: 1 | E29: 3 | F29: 3 | G29: 67.24 | H29: 63.655 | I29: 67.5 | L29: 71.53 | M29: SEM COTAÇÃO | Q29: sem estoque na Nazária; sem estoque no ePan
A30: 364041 | B30: 7891317172749 | C30: AZOX 20MG/ML PO SUS OR FR 100ML+SER DOS | D30: 1 | E30: 1 | F30: 1 | G30: 46.74 | H30: 42.955 | K30: 46.74 | M30: TAPAJOS | N30: 46.74 | O30: =N30/G30-1 | P30: OK (≤ últ. compra)
A31: 645591 | B31: 7898040328603 | C31: BACTRIM F CX 10 COMP | D31: 1 | E31: 5 | F31: 5 | G31: 27.55 | H31: 24.63 | J31: 28 | K31: 27.55 | L31: 27.455 | M31: NAZARIA | N31: 27.455 | O31: =N31/G31-1 | P31: OK (≤ últ. compra)
A32: 339861 | B32: 7896004726793 | C32: BALSAMO BENGUE 0,10+0,50G AER FR 60G | D32: 1 | E32: 1 | F32: 1 | G32: 28.88 | H32: 25.51 | K32: 34.71 | L32: 36.93 | M32: TAPAJOS | N32: 34.71 | O32: =N32/G32-1 | P32: ACIMA +20.2% (vs últ. compra)
A33: 339821 | B33: 7896004817576 | C33: BALSAMO BENGUE GEL BG 20G | D33: 1 | E33: 2 | F33: 2 | G33: 19.96 | H33: 13.96 | K33: 19.96 | L33: 21.23 | M33: TAPAJOS | N33: 19.96 | O33: =N33/G33-1 | P33: OK (≤ últ. compra) | Q33: sem estoque na Nazária
A34: 596541 | B34: 7891317026554 | C34: BEDOZE 5MG/ML SOL INJ 2 AMP X 1ML | D34: 1 | E34: 1 | F34: 1 | G34: 32.8 | H34: 30.2 | I34: 32.8 | J34: 32.9 | K34: 31.9 | L34: 32.5824 | M34: TAPAJOS | N34: 31.9 | O34: =N34/G34-1 | P34: OK (≤ últ. compra)
A35: 114701 | B35: 7891010974923 | C35: BENALET 5+50+10MG PASTILHA CARTELA MEL/LIMAO C/ 4UN | D35: 13 | E35: 1 | F35: 13 | G35: 10.619115 | H35: 10.1792 | M35: SEM COTAÇÃO
A36: 497121 | B36: 7891268402025 | C36: BENALET 5+50+10MG PASTILHA SB MEL E LIMAO CX C/ 12UN | D36: 1 | E36: 2 | F36: 2 | G36: 9.5166667 | H36: 9.5166667 | M36: SEM COTAÇÃO
A37: 114681 | B37: 7891010974930 | C37: BENALET 5+50+10MG PASTILHA SB MENTA CX C/ 12UN | D37: 1 | E37: 1 | F37: 1 | G37: 24.88 | H37: 24.88 | M37: SEM COTAÇÃO
A38: 54421 | B38: 7897411611023 | C38: BENICAR ANLO 40+5MG CX 30 COMP REV | D38: 1 | E38: 3 | F38: 3 | G38: 76.89 | H38: 68.46 | I38: 76.89 | J38: 75.5 | L38: 77.87 | M38: SB LOG | N38: 75.5 | O38: =N38/G38-1 | P38: OK (≤ últ. compra)
A39: 588821 | B39: 7891106912167 | C39: BEPANTOL BABY 30+15G | D39: 1 | E39: 9 | F39: 9 | G39: 14.36 | H39: 12.9012 | J39: 12.7 | K39: 14.83 | L39: 19.44 | M39: SB LOG | N39: 12.7 | O39: =N39/G39-1 | P39: OK (≤ menor hist.)
A40: 550701 | B40: 7891106907286 | C40: BEPANTOL DERMA CR 20GR | D40: 1 | E40: 6 | F40: 6 | G40: 23.83 | H40: 23.4233 | I40: 25.64 | J40: 20.8 | K40: 23.83 | L40: 31.89 | M40: SB LOG | N40: 20.8 | O40: =N40/G40-1 | P40: OK (≤ menor hist.)
...

Sheet Sem_Cotacao
A1: Cód. interno | B1: EAN princ. | C1: Produto | D1: Un/Cx | E1: Caixas | F1: Un. compradas | G1: Menor hist. (un) | H1: Motivo
A2: 71981 | B2: 7896676414639 | C2: ANA-FLEX 35+300+50MG CX 200 COMP | D2: 20 | E2: 1 | F2: 20 | G2: 4.9505 | H2: nenhum distribuidor cotou
A3: 131861 | B3: 7896094200227 | C3: ANSITEC 5MG CX 20 COMP | D3: 1 | E3: 1 | F3: 1 | G3: 27.07 | H3: nenhum distribuidor cotou
A4: 624171 | B4: 7899706195089 | C4: ANTHELIOS LRP AIRLIC FL FPS50 S/COR 40ML | D4: 1 | E4: 1 | F4: 1 | G4: 88.16 | H4: nenhum distribuidor cotou
A5: 618051 | B5: 7908615030098 | C5: ANTHELIOS LRP AIRLIC FPS70 2.0 40G+NECESSARIE | D5: 1 | E5: 1 | F5: 1 | G5: 75.475 | H5: nenhum distribuidor cotou
A6: 648861 | B6: 7908615038384 | C6: ANTHELIOS LRP AIRLIC+FLUIDO FPS50+EFFACL CONC 50G | D6: 1 | E6: 1 | F6: 1 | G6: 112.82 | H6: sem estoque na Nazária
A7: 666011 | B7: 7898639690586 | C7: APAR PRES DIG HOME GP200 G-TECH-DEMAIS PROD | D7: 1 | E7: 2 | F7: 2 | G7: 73.0383 | H7: nenhum distribuidor cotou
A8: 619611 | B8: 7898636190720 | C8: ASEPXIA PO COMPA MARFIM 10G | D8: 1 | E8: 1 | F8: 1 | G8: 36.43 | H8: nenhum distribuidor cotou
A9: 13921 | B9: 7891106915175 | C9: ASPIRINA 500MG CX 100 COMP ACLAR | D9: 10 | E9: 1 | F9: 10 | G9: 7.2447 | H9: nenhum distribuidor cotou
A10: 15761 | B10: 5702191025637 | C10: AZELAN 150 MG/G GEL CT BG AL X 30 G | D10: 1 | E10: 3 | F10: 3 | G10: 63.655 | H10: sem estoque no ePan; sem estoque na Nazária
A11: 114701 | B11: 7891010974923 | C11: BENALET 5+50+10MG PASTILHA CARTELA MEL/LIMAO C/ 4UN | D11: 13 | E11: 1 | F11: 13 | G11: 10.1792 | H11: nenhum distribuidor cotou
A12: 497121 | B12: 7891268402025 | C12: BENALET 5+50+10MG PASTILHA SB MEL E LIMAO CX C/ 12UN | D12: 1 | E12: 2 | F12: 2 | G12: 9.5166667 | H12: nenhum distribuidor cotou
A13: 114681 | B13: 7891010974930 | C13: BENALET 5+50+10MG PASTILHA SB MENTA CX C/ 12UN | D13: 1 | E13: 1 | F13: 1 | G13: 24.88 | H13: nenhum distribuidor cotou
... A31: 666711 | B31: 7891317042202 | C31: DOZI 1000MCG C/30 COMP SUB-OUTROS | D31: 1 | E31: 1 | F31: 1 | G31: 44.048 | H31: sem estoque no ePan
A32: 669071 | C32: DRAMIN CAPS GEL (CARTELADO) PV | D32: 1 | E32: 1 | F32: 1 | H32: nenhum distribuidor cotou
A33: 655311 | B33: 7891317027179 | C33: DUALGI 200MG+500MG 12CPR | D33: 1 | E33: 2 | F33: 2 | G33: 23.93 | H33: sem estoque no ePan; sem estoque na Nazária
A34: 658021 | B34: 4005900995520 | C34: EUCERIN HYDRO FLUID SUN FPS60 50ML | D34: 1 | E34: 1 | F34: 1 | G34: 75.47 | H34: sem estoque na Nazária
A35: 626071 | B35: 7896023756849 | C35: FIGATIL 10ML FLACONETE | D35: 48 | E35: 1 | F35: 48 | G35: 1.1388 | H35: nenhum distribuidor cotou
A36: 652451 | C36: FLOGORAL CARTELA 4 PAST SB LARANJA | D36: 3 | E36: 3 | F36: 9 | H36: nenhum distribuidor cotou
A37: 638781 | B37: 040141785435 | C37: FORTMAGRI 1500MG 60 CPS (BERBERINA+FENO+MOROSIL+CROMO) | D37: 1 | E37: 1 | F37: 1 | G37: 79.9 | H37: nenhum distribuidor cotou
A38: 622611 | B38: 5000456070423 | C38: FORXIGA 10MG CX 30 COMP | D38: 1 | E38: 2 | F38: 2 | G38: 164.855 | H38: nenhum distribuidor cotou
A39: 595291 | B39: 7898495609289 | C39: GROW CALCIO 150ML + SER DOS | D39: 1 | E39: 1 | F39: 1 | G39: 59.83 | H39: nenhum distribuidor cotou
A40: 627211 | B40: 7908020501435 | C40: GROW D 10ML-DEMAIS PROD | D40: 1 | E40: 1 | F40: 1 | G40: 39.47 | H40: sem estoque na Nazária
A41: 559601 | B41: 7898495609326 | C41: GROW VIT BB C/20ML (CFE) | D41: 1 | E41: 1 | F41: 1 | G41: 37.1 | H41: sem estoque na Nazária
A42: 619571 | B42: 4005900163875 | C42: HIDRAT NIVEA ANTIC PERNAS RENOV 400ML NIVE %DN:2.00 | D42: 1 | E42: 1 | F42: 1 | G42: 35.4725 | H42: nenhum distribuidor cotou
A43: 153101 | B43: 7896212478750 | C43: IMOSEC 2MG CX 12 COMP | D43: 1 | E43: 25 | F43: 25 | G43: 8.3991 | H43: nenhum distribuidor cotou
A44: 594881 | B44: 7898639690975 | C44: INALADOR NEBULIZADOR COMPACT DC1 G-TECH | D44: 1 | E44: 1 | F44: 1 | G44: 90.756 | H44: nenhum distribuidor cotou
A45: 570201 | B45: 7896004762098 | C45: LACDAY 8CPR MAST | D45: 1 | E45: 2 | F45: 2 | G45: 16.73 | H45: sem estoque na Nazária
A46: 1183 | B46: 7898639691965 | C46: LANCETAS PARA LANCETADOR 30G C/50 UND | D46: 1 | E46: 1 | F46: 1 | G46: 2.84 | H46: nenhum distribuidor cotou
A47: 655561 | B47: 7891317029869 | C47: LARC 500MG C/14 COMP-SIMILAR | D47: 1 | E47: 1 | F47: 1 | G47: 33.36 | H47: sem estoque na Nazária
A48: 623531 | B48: 3337875803786 | C48: LIPIKAR BAUME LIGHT AP+M 400ML-DEMAIS PROD | D48: 1 | E48: 1 | F48: 1 | G48: 162.55 | H48: sem estoque na Nazária
... A65: 611031 | B65: 4015630064205 | C65: N ACCU-CHEK ACTIVE 10TIRAS ROCH %DN:0.00 | D65: 1 | E65: 1 | F65: 1 | G65: 29.16 | H65: sem estoque na Nazária
A66: 579461 | C66: NALDECON MULTI 800+20MG CARTELA C/ 4 CP | D66: 10 | E66: 1 | F66: 10 | G66: 6.8011 | H66: nenhum distribuidor cotou
A67: 16441 | B67: 7894916500425 | C67: NEUTROFER FOLICO 150MG FR 30 COMP | D67: 1 | E67: 1 | F67: 1 | G67: 34.355 | H67: sem estoque no ePan; sem estoque na Nazária
A68: 652651 | B68: 4005900929679 | C68: NIVEA VISAGE CELLULLAR LIFT EXPERT DIA SPF 30 50GRS | D68: 1 | E68: 1 | F68: 1 | G68: 50.02 | H68: nenhum distribuidor cotou
A69: 588811 | B69: 7898581710547 | C69: NORIPURUM 100MG CX 30 COMP MAST | D69: 1 | E69: 5 | F69: 5 | G69: 52.5033 | H69: sem estoque no ePan; sem estoque na Nazária
A70: 601521 | B70: 7898581710615 | C70: NORIPURUM ENDOV INJ 5 AMP X 5ML | D70: 1 | E70: 1 | F70: 1 | G70: 68.31 | H70: sem estoque no ePan; sem estoque na Nazária
A71: TOTAL GERAL | D71: 1152 | E71: 2072 | F71: 3234 | H71: nenhum distribuidor cotou
A72: 565041 | B72: 78900813 | C72: PASTILHAS VALDA CLASSIC 24G | D72: 12 | E72: 1 | F72: 12 | G72: 4.6233 | H72: nenhum distribuidor cotou
A73: 652011 | B73: 7891158106460 | C73: PEDIALYTE MAX COCO 500ML | D73: 1 | E73: 2 | F73: 2 | G73: 20.09 | H73: sem estoque no ePan
...
